<sdf version="1.7">
  <world name="sim_world">
    <physics name="10ms" type="ode">
      <max_step_size>0.01</max_step_size>
      <real_time_factor>1.0</real_time_factor>
    </physics>
    <plugin filename="gz-sim-physics-system" name="gz::sim::systems::Physics">
    </plugin>
    <plugin filename="gz-sim-user-commands-system" name="gz::sim::systems::UserCommands">
    </plugin>
    <plugin filename="gz-sim-scene-broadcaster-system" name="gz::sim::systems::SceneBroadcaster">
    </plugin>
    <plugin filename="libdoor.so" name="door">
    </plugin>
    <plugin filename="liblift.so" name="lift">
    </plugin>
    <scene>
      <ambient>1 1 1</ambient>
      <background>0.8 0.8 0.8</background>
      <grid>false</grid>
    </scene>
    <gui fullscreen="0">
      <window>
        <width>1000</width>
        <height>845</height>
        <style material_theme="Light" material_primary="DeepOrange" material_accent="LightBlue" toolbar_color_light="#f3f3f3" toolbar_text_color_light="#111111" toolbar_color_dark="#414141" toolbar_text_color_dark="#f3f3f3" plugin_toolbar_color_light="#bbdefb" plugin_toolbar_text_color_light="#111111" plugin_toolbar_color_dark="#607d8b" plugin_toolbar_text_color_dark="#eeeeee" />
        <menus>
          <drawer default="false">
          </drawer>
        </menus>
      </window>
      <plugin filename="MinimalScene" name="3D View">
        <gz-gui>
          <title>3D View</title>
          <property type="bool" key="showTitleBar">false</property>
          <property type="string" key="state">docked</property>
        </gz-gui>
        <engine>ogre2</engine>
        <scene>scene</scene>
        <ambient_light>0.4 0.4 0.4</ambient_light>
        <background_color>0.8 0.8 0.8</background_color>
        <camera_pose>16.655918367346942 -42.98885204081633 10 0 0.6 1.57</camera_pose>
      </plugin>
      <plugin filename="EntityContextMenuPlugin" name="Entity context menu">
        <gz-gui>
          <property key="state" type="string">floating</property>
          <property key="width" type="double">5</property>
          <property key="height" type="double">5</property>
          <property key="showTitleBar" type="bool">false</property>
        </gz-gui>
      </plugin>
      <plugin filename="GzSceneManager" name="Scene Manager">
        <gz-gui>
          <property key="resizable" type="bool">false</property>
          <property key="width" type="double">5</property>
          <property key="height" type="double">5</property>
          <property key="state" type="string">floating</property>
          <property key="showTitleBar" type="bool">false</property>
        </gz-gui>
      </plugin>
      <plugin filename="InteractiveViewControl" name="Interactive view control">
        <gz-gui>
          <property key="resizable" type="bool">false</property>
          <property key="width" type="double">5</property>
          <property key="height" type="double">5</property>
          <property key="state" type="string">floating</property>
          <property key="showTitleBar" type="bool">false</property>
        </gz-gui>
      </plugin>
      <plugin filename="CameraTracking" name="Camera Tracking">
        <gz-gui>
          <property key="resizable" type="bool">false</property>
          <property key="width" type="double">5</property>
          <property key="height" type="double">5</property>
          <property key="state" type="string">floating</property>
          <property key="showTitleBar" type="bool">false</property>
        </gz-gui>
      </plugin>
      <plugin filename="MarkerManager" name="Marker manager">
        <gz-gui>
          <property key="resizable" type="bool">false</property>
          <property key="width" type="double">5</property>
          <property key="height" type="double">5</property>
          <property key="state" type="string">floating</property>
          <property key="showTitleBar" type="bool">false</property>
        </gz-gui>
      </plugin>
      <plugin filename="SelectEntities" name="Select Entities">
        <gz-gui>
          <property key="resizable" type="bool">false</property>
          <property key="width" type="double">5</property>
          <property key="height" type="double">5</property>
          <property key="state" type="string">floating</property>
          <property key="showTitleBar" type="bool">false</property>
        </gz-gui>
      </plugin>
      <plugin filename="Spawn" name="Spawn Entities">
        <gz-gui>
          <property key="resizable" type="bool">false</property>
          <property key="width" type="double">5</property>
          <property key="height" type="double">5</property>
          <property key="state" type="string">floating</property>
          <property key="showTitleBar" type="bool">false</property>
        </gz-gui>
      </plugin>
      <plugin filename="VisualizationCapabilities" name="Visualization Capabilities">
        <gz-gui>
          <property key="resizable" type="bool">false</property>
          <property key="width" type="double">5</property>
          <property key="height" type="double">5</property>
          <property key="state" type="string">floating</property>
          <property key="showTitleBar" type="bool">false</property>
        </gz-gui>
      </plugin>
      <plugin filename="WorldControl" name="World control">
        <gz-gui>
          <title>World control</title>
          <property type="bool" key="showTitleBar">false</property>
          <property type="bool" key="resizable">false</property>
          <property type="double" key="height">72</property>
          <property type="double" key="z">1</property>
          <property type="string" key="state">floating</property>
          <anchors target="3D View">
            <line own="left" target="left" />
            <line own="bottom" target="bottom" />
          </anchors>
        </gz-gui>
        <play_pause>true</play_pause>
        <step>true</step>
        <start_paused>true</start_paused>
        <use_event>true</use_event>
      </plugin>
      <plugin filename="WorldStats" name="World stats">
        <gz-gui>
          <title>World stats</title>
          <property type="bool" key="showTitleBar">false</property>
          <property type="bool" key="resizable">false</property>
          <property type="double" key="height">110</property>
          <property type="double" key="width">290</property>
          <property type="double" key="z">1</property>
          <property type="string" key="state">floating</property>
          <anchors target="3D View">
            <line own="right" target="right" />
            <line own="bottom" target="bottom" />
          </anchors>
        </gz-gui>
        <sim_time>true</sim_time>
        <real_time>true</real_time>
        <real_time_factor>true</real_time_factor>
        <iterations>true</iterations>
      </plugin>
      <plugin filename="Shapes" name="Shapes">
        <gz-gui>
          <property key="resizable" type="bool">false</property>
          <property key="x" type="double">0</property>
          <property key="y" type="double">0</property>
          <property key="width" type="double">250</property>
          <property key="height" type="double">50</property>
          <property key="state" type="string">floating</property>
          <property key="showTitleBar" type="bool">false</property>
          <property key="cardBackground" type="string">#666666</property>
        </gz-gui>
      </plugin>
      <plugin filename="Lights" name="Lights">
        <gz-gui>
          <property key="resizable" type="bool">false</property>
          <property key="x" type="double">250</property>
          <property key="y" type="double">0</property>
          <property key="width" type="double">150</property>
          <property key="height" type="double">50</property>
          <property key="state" type="string">floating</property>
          <property key="showTitleBar" type="bool">false</property>
          <property key="cardBackground" type="string">#666666</property>
        </gz-gui>
      </plugin>
      <plugin filename="TransformControl" name="Transform control">
        <gz-gui>
          <property key="resizable" type="bool">false</property>
          <property key="x" type="double">0</property>
          <property key="y" type="double">50</property>
          <property key="width" type="double">250</property>
          <property key="height" type="double">50</property>
          <property key="state" type="string">floating</property>
          <property key="showTitleBar" type="bool">false</property>
          <property key="cardBackground" type="string">#777777</property>
        </gz-gui>
      </plugin>
      <plugin filename="Screenshot" name="Screenshot">
        <gz-gui>
          <property key="resizable" type="bool">false</property>
          <property key="x" type="double">250</property>
          <property key="y" type="double">50</property>
          <property key="width" type="double">50</property>
          <property key="height" type="double">50</property>
          <property key="state" type="string">floating</property>
          <property key="showTitleBar" type="bool">false</property>
          <property key="cardBackground" type="string">#777777</property>
        </gz-gui>
      </plugin>
      <plugin filename="CopyPaste" name="CopyPaste">
        <gz-gui>
          <property key="resizable" type="bool">false</property>
          <property key="x" type="double">300</property>
          <property key="y" type="double">50</property>
          <property key="width" type="double">100</property>
          <property key="height" type="double">50</property>
          <property key="state" type="string">floating</property>
          <property key="showTitleBar" type="bool">false</property>
          <property key="cardBackground" type="string">#777777</property>
        </gz-gui>
      </plugin>
      <plugin filename="ComponentInspector" name="Component inspector">
        <gz-gui>
          <property type="bool" key="showTitleBar">false</property>
          <property type="string" key="state">docked</property>
        </gz-gui>
      </plugin>
      <plugin filename="EntityTree" name="Entity tree">
        <gz-gui>
          <property type="bool" key="showTitleBar">false</property>
          <property type="string" key="state">docked</property>
        </gz-gui>
      </plugin>
      <plugin filename="toggle_charging" name="toggle_charging" />
      <plugin name="toggle_floors" filename="toggle_floors">
        <floor name="L1" model_name="icc_kyoto_L1">
          <model name="OpenRobotics/AdjTable" />
          <model name="OpenRobotics/AdjTable_2" />
          <model name="OpenRobotics/AdjTable_3" />
          <model name="OpenRobotics/AdjTable_4" />
          <model name="OpenRobotics/AdjTable_5" />
          <model name="OpenRobotics/AdjTable_6" />
          <model name="OpenRobotics/AdjTable_7" />
          <model name="OpenRobotics/AdjTable_8" />
          <model name="OpenRobotics/AdjTable_9" />
          <model name="OpenRobotics/AdjTable_10" />
          <model name="OpenRobotics/AdjTable_11" />
          <model name="OpenRobotics/AdjTable_12" />
          <model name="OpenRobotics/AdjTable_13" />
          <model name="OpenRobotics/AdjTable_14" />
          <model name="OpenRobotics/AdjTable_15" />
          <model name="OpenRobotics/AdjTable_16" />
          <model name="OpenRobotics/AdjTable_17" />
          <model name="OpenRobotics/AdjTable_18" />
          <model name="OpenRobotics/AdjTable_19" />
          <model name="OpenRobotics/AdjTable_20" />
          <model name="OpenRobotics/AdjTable_21" />
          <model name="OpenRobotics/AdjTable_22" />
          <model name="OpenRobotics/AdjTable_23" />
          <model name="OpenRobotics/AdjTable_24" />
          <model name="OpenRobotics/AdjTable_25" />
          <model name="OpenRobotics/AdjTable_26" />
          <model name="OpenRobotics/AdjTable_27" />
          <model name="OpenRobotics/AdjTable_28" />
          <model name="OpenRobotics/AdjTable_29" />
          <model name="OpenRobotics/AdjTable_30" />
          <model name="OpenRobotics/AdjTable_31" />
          <model name="OpenRobotics/AdjTable_32" />
          <model name="OpenRobotics/AdjTable_33" />
          <model name="OpenRobotics/AdjTable_34" />
          <model name="OpenRobotics/AdjTable_35" />
          <model name="OpenRobotics/AdjTable_36" />
          <model name="OpenRobotics/AdjTable_37" />
          <model name="OpenRobotics/AdjTable_38" />
          <model name="OpenRobotics/AdjTable_39" />
          <model name="OpenRobotics/AdjTable_40" />
          <model name="OpenRobotics/AdjTable_41" />
          <model name="OpenRobotics/AdjTable_42" />
          <model name="OpenRobotics/AdjTable_43" />
          <model name="OpenRobotics/AdjTable_44" />
          <model name="OpenRobotics/AdjTable_45" />
          <model name="OpenRobotics/AdjTable_46" />
          <model name="OpenRobotics/AdjTable_47" />
          <model name="OpenRobotics/AdjTable_48" />
          <model name="OpenRobotics/AdjTable_49" />
          <model name="OpenRobotics/AdjTable_50" />
          <model name="OpenRobotics/AdjTable_51" />
          <model name="OpenRobotics/AdjTable_52" />
          <model name="OpenRobotics/AdjTable_53" />
          <model name="OpenRobotics/AdjTable_54" />
          <model name="OpenRobotics/AdjTable_55" />
          <model name="OpenRobotics/AdjTable_56" />
          <model name="OpenRobotics/AdjTable_57" />
          <model name="OpenRobotics/AdjTable_58" />
          <model name="OpenRobotics/AdjTable_59" />
          <model name="OpenRobotics/AdjTable_60" />
          <model name="OpenRobotics/AdjTable_61" />
          <model name="OpenRobotics/AdjTable_62" />
          <model name="OpenRobotics/OfficeChairGrey" />
          <model name="OpenRobotics/OfficeChairGrey_2" />
          <model name="OpenRobotics/OfficeChairGrey_3" />
          <model name="OpenRobotics/OfficeChairGrey_4" />
          <model name="OpenRobotics/OfficeChairGrey_5" />
          <model name="OpenRobotics/OfficeChairGrey_6" />
          <model name="OpenRobotics/OfficeChairGrey_7" />
          <model name="OpenRobotics/OfficeChairGrey_8" />
          <model name="OpenRobotics/OfficeChairGrey_9" />
          <model name="OpenRobotics/OfficeChairGrey_10" />
          <model name="OpenRobotics/OfficeChairGrey_11" />
          <model name="OpenRobotics/OfficeChairGrey_12" />
          <model name="OpenRobotics/OfficeChairGrey_13" />
          <model name="OpenRobotics/OfficeChairGrey_14" />
          <model name="OpenRobotics/OfficeChairGrey_15" />
          <model name="OpenRobotics/OfficeChairGrey_16" />
          <model name="OpenRobotics/OfficeChairGrey_17" />
          <model name="OpenRobotics/OfficeChairGrey_18" />
          <model name="OpenRobotics/OfficeChairGrey_19" />
          <model name="OpenRobotics/OfficeChairGrey_20" />
          <model name="OpenRobotics/OfficeChairGrey_21" />
          <model name="OpenRobotics/OfficeChairGrey_22" />
          <model name="OpenRobotics/OfficeChairGrey_23" />
          <model name="OpenRobotics/OfficeChairGrey_24" />
          <model name="OpenRobotics/OfficeChairGrey_25" />
          <model name="OpenRobotics/OfficeChairGrey_26" />
          <model name="OpenRobotics/OfficeChairGrey_27" />
          <model name="OpenRobotics/OfficeChairGrey_28" />
          <model name="OpenRobotics/OfficeChairGrey_29" />
          <model name="OpenRobotics/OfficeChairGrey_30" />
          <model name="OpenRobotics/OfficeChairGrey_31" />
          <model name="OpenRobotics/OfficeChairGrey_32" />
          <model name="OpenRobotics/OfficeChairGrey_33" />
          <model name="OpenRobotics/OfficeChairGrey_34" />
          <model name="OpenRobotics/OfficeChairGrey_35" />
          <model name="OpenRobotics/OfficeChairGrey_36" />
          <model name="OpenRobotics/OfficeChairGrey_37" />
          <model name="OpenRobotics/OfficeChairGrey_38" />
          <model name="OpenRobotics/OfficeChairGrey_39" />
          <model name="OpenRobotics/OfficeChairGrey_40" />
          <model name="OpenRobotics/OfficeChairGrey_41" />
          <model name="OpenRobotics/OfficeChairGrey_42" />
          <model name="OpenRobotics/OfficeChairGrey_43" />
          <model name="OpenRobotics/OfficeChairGrey_44" />
          <model name="OpenRobotics/OfficeChairGrey_45" />
          <model name="OpenRobotics/OfficeChairGrey_46" />
          <model name="OpenRobotics/OfficeChairGrey_47" />
          <model name="OpenRobotics/OfficeChairGrey_48" />
          <model name="OpenRobotics/OfficeChairGrey_49" />
          <model name="OpenRobotics/OfficeChairGrey_50" />
          <model name="OpenRobotics/OfficeChairGrey_51" />
          <model name="OpenRobotics/OfficeChairGrey_52" />
          <model name="OpenRobotics/OfficeChairGrey_53" />
          <model name="OpenRobotics/OfficeChairGrey_54" />
          <model name="OpenRobotics/OfficeChairGrey_55" />
          <model name="OpenRobotics/OfficeChairGrey_56" />
          <model name="OpenRobotics/OfficeChairGrey_57" />
          <model name="OpenRobotics/OfficeChairGrey_58" />
          <model name="OpenRobotics/OfficeChairGrey_59" />
          <model name="OpenRobotics/OfficeChairGrey_60" />
          <model name="OpenRobotics/OfficeChairGrey_61" />
          <model name="OpenRobotics/OfficeChairGrey_62" />
          <model name="OpenRobotics/OfficeChairGrey_63" />
          <model name="OpenRobotics/OfficeChairGrey_64" />
          <model name="OpenRobotics/OfficeChairGrey_65" />
          <model name="OpenRobotics/OfficeChairGrey_66" />
          <model name="OpenRobotics/OfficeChairGrey_67" />
          <model name="OpenRobotics/OfficeChairGrey_68" />
          <model name="OpenRobotics/OfficeChairGrey_69" />
          <model name="OpenRobotics/OfficeChairGrey_70" />
          <model name="OpenRobotics/OfficeChairGrey_71" />
          <model name="OpenRobotics/OfficeChairGrey_72" />
          <model name="OpenRobotics/OfficeChairGrey_73" />
          <model name="OpenRobotics/OfficeChairGrey_74" />
          <model name="OpenRobotics/OfficeChairGrey_75" />
          <model name="OpenRobotics/OfficeChairGrey_76" />
          <model name="OpenRobotics/OfficeChairGrey_77" />
          <model name="OpenRobotics/OfficeChairGrey_78" />
          <model name="OpenRobotics/OfficeChairGrey_79" />
          <model name="OpenRobotics/OfficeChairGrey_80" />
          <model name="OpenRobotics/OfficeChairGrey_81" />
          <model name="OpenRobotics/OfficeChairGrey_82" />
          <model name="OpenRobotics/OfficeChairGrey_83" />
          <model name="OpenRobotics/OfficeChairGrey_84" />
          <model name="OpenRobotics/OfficeChairGrey_85" />
          <model name="OpenRobotics/OfficeChairGrey_86" />
          <model name="OpenRobotics/OfficeChairGrey_87" />
          <model name="OpenRobotics/OfficeChairGrey_88" />
          <model name="OpenRobotics/OfficeChairGrey_89" />
          <model name="OpenRobotics/OfficeChairGrey_90" />
          <model name="OpenRobotics/OfficeChairGrey_91" />
          <model name="OpenRobotics/OfficeChairGrey_92" />
          <model name="OpenRobotics/OfficeChairGrey_93" />
          <model name="OpenRobotics/OfficeChairGrey_94" />
          <model name="OpenRobotics/OfficeChairGrey_95" />
          <model name="OpenRobotics/OfficeChairGrey_96" />
          <model name="OpenRobotics/OfficeChairGrey_97" />
          <model name="OpenRobotics/OfficeChairGrey_98" />
          <model name="OpenRobotics/OfficeChairGrey_99" />
          <model name="OpenRobotics/OfficeChairGrey_100" />
          <model name="OpenRobotics/OfficeChairGrey_101" />
          <model name="OpenRobotics/OfficeChairGrey_102" />
          <model name="OpenRobotics/OfficeChairGrey_103" />
          <model name="OpenRobotics/OfficeChairGrey_104" />
          <model name="OpenRobotics/OfficeChairGrey_105" />
          <model name="OpenRobotics/OfficeChairGrey_106" />
          <model name="OpenRobotics/OfficeChairGrey_107" />
          <model name="OpenRobotics/OfficeChairGrey_108" />
          <model name="OpenRobotics/OfficeChairGrey_109" />
          <model name="OpenRobotics/OfficeChairGrey_110" />
          <model name="OpenRobotics/OfficeChairGrey_111" />
          <model name="OpenRobotics/OfficeChairGrey_112" />
          <model name="OpenRobotics/OfficeChairGrey_113" />
          <model name="OpenRobotics/OfficeChairGrey_114" />
          <model name="OpenRobotics/OfficeChairGrey_115" />
          <model name="OpenRobotics/OfficeChairGrey_116" />
          <model name="OpenRobotics/OfficeChairGrey_117" />
          <model name="OpenRobotics/OfficeChairGrey_118" />
          <model name="OpenRobotics/OfficeChairGrey_119" />
          <model name="OpenRobotics/OfficeChairGrey_120" />
          <model name="OpenRobotics/OfficeChairGrey_121" />
          <model name="OpenRobotics/OfficeChairGrey_122" />
          <model name="door1" />
          <model name="door2" />
          <model name="door3" />
          <model name="door4" />
          <model name="door5" />
        </floor>
        <floor name="L2" model_name="icc_kyoto_L2">
          <model name="door6" />
          <model name="door7" />
          <model name="door8" />
          <model name="door9" />
        </floor>
      </plugin>
    </gui>
    <light type="directional" name="sun">
      <cast_shadows>true</cast_shadows>
      <pose>0 0 10 0 0 0</pose>
      <diffuse>1 1 1 1</diffuse>
      <specular>0.2 0.2 0.2 1</specular>
      <attenuation>
        <range>1000</range>
        <constant>0.09</constant>
        <linear>0.001</linear>
        <quadratic>0.001</quadratic>
      </attenuation>
      <direction>-0.5 0.1 -0.9</direction>
    </light>
    <include>
      <name>OpenRobotics/AdjTable</name>
      <uri>https://fuel.gazebosim.org/1.0/OpenRobotics/models/AdjTable</uri>
      <pose>15.830484693877555 -11.298775510204084 0.0 0 0 -3.1416</pose>
      <static>True</static>
    </include>
    <include>
      <name>OpenRobotics/AdjTable_2</name>
      <uri>https://fuel.gazebosim.org/1.0/OpenRobotics/models/AdjTable</uri>
      <pose>17.42336734693878 -11.299642857142862 0.0 0 0 -3.1416</pose>
      <static>True</static>
    </include>
    <include>
      <name>OpenRobotics/AdjTable_3</name>
      <uri>https://fuel.gazebosim.org/1.0/OpenRobotics/models/AdjTable</uri>
      <pose>15.847882653061228 -12.777780612244902 0.0 0 0 3.1416</pose>
      <static>True</static>
    </include>
    <include>
      <name>OpenRobotics/AdjTable_4</name>
      <uri>https://fuel.gazebosim.org/1.0/OpenRobotics/models/AdjTable</uri>
      <pose>17.416377551020414 -12.785943877551023 0.0 0 0 -3.1416</pose>
      <static>True</static>
    </include>
    <include>
      <name>OpenRobotics/AdjTable_5</name>
      <uri>https://fuel.gazebosim.org/1.0/OpenRobotics/models/AdjTable</uri>
      <pose>15.811479591836738 -14.230357142857148 0.0 0 0 3.1416</pose>
      <static>True</static>
    </include>
    <include>
      <name>OpenRobotics/AdjTable_6</name>
      <uri>https://fuel.gazebosim.org/1.0/OpenRobotics/models/AdjTable</uri>
      <pose>17.388801020408167 -14.22418367346939 0.0 0 0 3.1416</pose>
      <static>True</static>
    </include>
    <include>
      <name>OpenRobotics/AdjTable_7</name>
      <uri>https://fuel.gazebosim.org/1.0/OpenRobotics/models/AdjTable</uri>
      <pose>15.846377551020412 -15.57010204081633 0.0 0 0 -3.1416</pose>
      <static>True</static>
    </include>
    <include>
      <name>OpenRobotics/AdjTable_8</name>
      <uri>https://fuel.gazebosim.org/1.0/OpenRobotics/models/AdjTable</uri>
      <pose>17.451275510204088 -15.563112244897962 0.0 0 0 -3.1416</pose>
      <static>True</static>
    </include>
    <include>
      <name>OpenRobotics/AdjTable_9</name>
      <uri>https://fuel.gazebosim.org/1.0/OpenRobotics/models/AdjTable</uri>
      <pose>15.865280612244902 -16.93408163265307 0.0 0 0 -3.1416</pose>
      <static>True</static>
    </include>
    <include>
      <name>OpenRobotics/AdjTable_10</name>
      <uri>https://fuel.gazebosim.org/1.0/OpenRobotics/models/AdjTable</uri>
      <pose>17.433775510204086 -16.923928571428576 0.0 0 0 -3.1416</pose>
      <static>True</static>
    </include>
    <include>
      <name>OpenRobotics/AdjTable_11</name>
      <uri>https://fuel.gazebosim.org/1.0/OpenRobotics/models/AdjTable</uri>
      <pose>15.836326530612249 -18.38410714285715 0.0 0 0 -3.1416</pose>
      <static>True</static>
    </include>
    <include>
      <name>OpenRobotics/AdjTable_12</name>
      <uri>https://fuel.gazebosim.org/1.0/OpenRobotics/models/AdjTable</uri>
      <pose>17.429923469387763 -18.41255102040817 0.0 0 0 -3.1416</pose>
      <static>True</static>
    </include>
    <include>
      <name>OpenRobotics/AdjTable_13</name>
      <uri>https://fuel.gazebosim.org/1.0/OpenRobotics/models/AdjTable</uri>
      <pose>15.80788265306123 -19.678903061224496 0.0 0 0 -3.1416</pose>
      <static>True</static>
    </include>
    <include>
      <name>OpenRobotics/AdjTable_14</name>
      <uri>https://fuel.gazebosim.org/1.0/OpenRobotics/models/AdjTable</uri>
      <pose>17.41571428571429 -19.76428571428572 0.0 0 0 3.1416</pose>
      <static>True</static>
    </include>
    <include>
      <name>OpenRobotics/AdjTable_15</name>
      <uri>https://fuel.gazebosim.org/1.0/OpenRobotics/models/AdjTable</uri>
      <pose>15.846581632653066 -21.259234693877556 0.0 0 0 3.1416</pose>
      <static>True</static>
    </include>
    <include>
      <name>OpenRobotics/AdjTable_16</name>
      <uri>https://fuel.gazebosim.org/1.0/OpenRobotics/models/AdjTable</uri>
      <pose>17.38283163265307 -21.2433418367347 0.0 0 0 -3.1416</pose>
      <static>True</static>
    </include>
    <include>
      <name>OpenRobotics/AdjTable_17</name>
      <uri>https://fuel.gazebosim.org/1.0/OpenRobotics/models/AdjTable</uri>
      <pose>15.779413265306127 -22.496173469387763 0.0 0 0 -3.1416</pose>
      <static>True</static>
    </include>
    <include>
      <name>OpenRobotics/AdjTable_18</name>
      <uri>https://fuel.gazebosim.org/1.0/OpenRobotics/models/AdjTable</uri>
      <pose>17.380586734693882 -22.50864795918368 0.0 0 0 3.1416</pose>
      <static>True</static>
    </include>
    <include>
      <name>OpenRobotics/AdjTable_19</name>
      <uri>https://fuel.gazebosim.org/1.0/OpenRobotics/models/AdjTable</uri>
      <pose>15.869821428571433 -24.033418367346947 0.0 0 0 -3.1416</pose>
      <static>True</static>
    </include>
    <include>
      <name>OpenRobotics/AdjTable_20</name>
      <uri>https://fuel.gazebosim.org/1.0/OpenRobotics/models/AdjTable</uri>
      <pose>17.461811224489804 -24.033418367346947 0.0 0 0 -3.1416</pose>
      <static>True</static>
    </include>
    <include>
      <name>OpenRobotics/AdjTable_21</name>
      <uri>https://fuel.gazebosim.org/1.0/OpenRobotics/models/AdjTable</uri>
      <pose>19.681377551020415 -24.01068877551021 0.0 0 0 -3.1416</pose>
      <static>True</static>
    </include>
    <include>
      <name>OpenRobotics/AdjTable_22</name>
      <uri>https://fuel.gazebosim.org/1.0/OpenRobotics/models/AdjTable</uri>
      <pose>21.194056122448988 -23.989974489795927 0.0 0 0 -3.1416</pose>
      <static>True</static>
    </include>
    <include>
      <name>OpenRobotics/AdjTable_23</name>
      <uri>https://fuel.gazebosim.org/1.0/OpenRobotics/models/AdjTable</uri>
      <pose>19.66385204081633 -22.619948979591843 0.0 0 0 3.1416</pose>
      <static>True</static>
    </include>
    <include>
      <name>OpenRobotics/AdjTable_24</name>
      <uri>https://fuel.gazebosim.org/1.0/OpenRobotics/models/AdjTable</uri>
      <pose>21.204413265306126 -22.580892857142864 0.0 0 0 -3.1416</pose>
      <static>True</static>
    </include>
    <include>
      <name>OpenRobotics/AdjTable_25</name>
      <uri>https://fuel.gazebosim.org/1.0/OpenRobotics/models/AdjTable</uri>
      <pose>19.75538265306123 -21.266556122448986 0.0 0 0 3.1416</pose>
      <static>True</static>
    </include>
    <include>
      <name>OpenRobotics/AdjTable_26</name>
      <uri>https://fuel.gazebosim.org/1.0/OpenRobotics/models/AdjTable</uri>
      <pose>21.348443877551027 -21.279566326530617 0.0 0 0 3.1416</pose>
      <static>True</static>
    </include>
    <include>
      <name>OpenRobotics/AdjTable_27</name>
      <uri>https://fuel.gazebosim.org/1.0/OpenRobotics/models/AdjTable</uri>
      <pose>19.682321428571434 -19.88568877551021 0.0 0 0 -3.1416</pose>
      <static>True</static>
    </include>
    <include>
      <name>OpenRobotics/AdjTable_28</name>
      <uri>https://fuel.gazebosim.org/1.0/OpenRobotics/models/AdjTable</uri>
      <pose>21.25313775510205 -19.84915816326531 0.0 0 0 3.1416</pose>
      <static>True</static>
    </include>
    <include>
      <name>OpenRobotics/AdjTable_29</name>
      <uri>https://fuel.gazebosim.org/1.0/OpenRobotics/models/AdjTable</uri>
      <pose>19.74352040816327 -18.46760204081633 0.0 0 0 3.1416</pose>
      <static>True</static>
    </include>
    <include>
      <name>OpenRobotics/AdjTable_30</name>
      <uri>https://fuel.gazebosim.org/1.0/OpenRobotics/models/AdjTable</uri>
      <pose>19.753903061224495 -17.017066326530617 0.0 0 0 -3.1352</pose>
      <static>True</static>
    </include>
    <include>
      <name>OpenRobotics/AdjTable_31</name>
      <uri>https://fuel.gazebosim.org/1.0/OpenRobotics/models/AdjTable</uri>
      <pose>19.70558673469388 -15.520586734693882 0.0 0 0 3.1416</pose>
      <static>True</static>
    </include>
    <include>
      <name>OpenRobotics/AdjTable_32</name>
      <uri>https://fuel.gazebosim.org/1.0/OpenRobotics/models/AdjTable</uri>
      <pose>19.72260204081633 -14.166683673469391 0.0 0 0 -3.1416</pose>
      <static>True</static>
    </include>
    <include>
      <name>OpenRobotics/AdjTable_33</name>
      <uri>https://fuel.gazebosim.org/1.0/OpenRobotics/models/AdjTable</uri>
      <pose>19.714081632653066 -12.770204081632656 0.0 0 0 -3.1416</pose>
      <static>True</static>
    </include>
    <include>
      <name>OpenRobotics/AdjTable_34</name>
      <uri>https://fuel.gazebosim.org/1.0/OpenRobotics/models/AdjTable</uri>
      <pose>19.680025510204086 -11.314132653061229 0.0 0 0 3.1416</pose>
      <static>True</static>
    </include>
    <include>
      <name>OpenRobotics/AdjTable_35</name>
      <uri>https://fuel.gazebosim.org/1.0/OpenRobotics/models/AdjTable</uri>
      <pose>21.287321428571435 -11.308188775510208 0.0 0 0 -3.1416</pose>
      <static>True</static>
    </include>
    <include>
      <name>OpenRobotics/AdjTable_36</name>
      <uri>https://fuel.gazebosim.org/1.0/OpenRobotics/models/AdjTable</uri>
      <pose>21.326198979591844 -18.468290816326537 0.0 0 0 -3.1416</pose>
      <static>True</static>
    </include>
    <include>
      <name>OpenRobotics/AdjTable_37</name>
      <uri>https://fuel.gazebosim.org/1.0/OpenRobotics/models/AdjTable</uri>
      <pose>21.354260204081637 -17.029005102040824 0.0 0 0 3.1416</pose>
      <static>True</static>
    </include>
    <include>
      <name>OpenRobotics/AdjTable_38</name>
      <uri>https://fuel.gazebosim.org/1.0/OpenRobotics/models/AdjTable</uri>
      <pose>21.30441326530613 -15.521683673469393 0.0 0 0 3.1416</pose>
      <static>True</static>
    </include>
    <include>
      <name>OpenRobotics/AdjTable_39</name>
      <uri>https://fuel.gazebosim.org/1.0/OpenRobotics/models/AdjTable</uri>
      <pose>21.249464285714293 -14.170178571428576 0.0 0 0 -3.1416</pose>
      <static>True</static>
    </include>
    <include>
      <name>OpenRobotics/AdjTable_40</name>
      <uri>https://fuel.gazebosim.org/1.0/OpenRobotics/models/AdjTable</uri>
      <pose>21.263826530612253 -12.770204081632656 0.0 0 0 3.1416</pose>
      <static>True</static>
    </include>
    <include>
      <name>OpenRobotics/AdjTable_41</name>
      <uri>https://fuel.gazebosim.org/1.0/OpenRobotics/models/AdjTable</uri>
      <pose>23.556352040816332 -11.339260204081636 0.0 0 0 3.1416</pose>
      <static>True</static>
    </include>
    <include>
      <name>OpenRobotics/AdjTable_42</name>
      <uri>https://fuel.gazebosim.org/1.0/OpenRobotics/models/AdjTable</uri>
      <pose>25.141581632653068 -11.339260204081636 0.0 0 0 3.1416</pose>
      <static>True</static>
    </include>
    <include>
      <name>OpenRobotics/AdjTable_43</name>
      <uri>https://fuel.gazebosim.org/1.0/OpenRobotics/models/AdjTable</uri>
      <pose>23.54051020408164 -12.749897959183677 0.0 0 0 -3.1416</pose>
      <static>True</static>
    </include>
    <include>
      <name>OpenRobotics/AdjTable_44</name>
      <uri>https://fuel.gazebosim.org/1.0/OpenRobotics/models/AdjTable</uri>
      <pose>23.60178571428572 -14.136938775510208 0.0 0 0 0.0</pose>
      <static>True</static>
    </include>
    <include>
      <name>OpenRobotics/AdjTable_45</name>
      <uri>https://fuel.gazebosim.org/1.0/OpenRobotics/models/AdjTable</uri>
      <pose>23.587448979591844 -15.639056122448986 0.0 0 0 3.1416</pose>
      <static>True</static>
    </include>
    <include>
      <name>OpenRobotics/AdjTable_46</name>
      <uri>https://fuel.gazebosim.org/1.0/OpenRobotics/models/AdjTable</uri>
      <pose>23.597806122448986 -17.017066326530617 0.0 0 0 3.1416</pose>
      <static>True</static>
    </include>
    <include>
      <name>OpenRobotics/AdjTable_47</name>
      <uri>https://fuel.gazebosim.org/1.0/OpenRobotics/models/AdjTable</uri>
      <pose>23.5770918367347 -18.436505102040822 0.0 0 0 3.1416</pose>
      <static>True</static>
    </include>
    <include>
      <name>OpenRobotics/AdjTable_48</name>
      <uri>https://fuel.gazebosim.org/1.0/OpenRobotics/models/AdjTable</uri>
      <pose>23.47443877551021 -19.826862244897963 0.0 0 0 3.1416</pose>
      <static>True</static>
    </include>
    <include>
      <name>OpenRobotics/AdjTable_49</name>
      <uri>https://fuel.gazebosim.org/1.0/OpenRobotics/models/AdjTable</uri>
      <pose>23.53428571428572 -21.250000000000007 0.0 0 0 -3.1416</pose>
      <static>True</static>
    </include>
    <include>
      <name>OpenRobotics/AdjTable_50</name>
      <uri>https://fuel.gazebosim.org/1.0/OpenRobotics/models/AdjTable</uri>
      <pose>23.54051020408164 -22.609642857142862 0.0 0 0 -3.1416</pose>
      <static>True</static>
    </include>
    <include>
      <name>OpenRobotics/AdjTable_51</name>
      <uri>https://fuel.gazebosim.org/1.0/OpenRobotics/models/AdjTable</uri>
      <pose>23.556352040816332 -24.10395408163266 0.0 0 0 -3.1416</pose>
      <static>True</static>
    </include>
    <include>
      <name>OpenRobotics/AdjTable_52</name>
      <uri>https://fuel.gazebosim.org/1.0/OpenRobotics/models/AdjTable</uri>
      <pose>25.08977040816327 -24.093571428571433 0.0 0 0 3.1416</pose>
      <static>True</static>
    </include>
    <include>
      <name>OpenRobotics/AdjTable_53</name>
      <uri>https://fuel.gazebosim.org/1.0/OpenRobotics/models/AdjTable</uri>
      <pose>25.139234693877558 -22.626352040816332 0.0 0 0 3.1416</pose>
      <static>True</static>
    </include>
    <include>
      <name>OpenRobotics/AdjTable_54</name>
      <uri>https://fuel.gazebosim.org/1.0/OpenRobotics/models/AdjTable</uri>
      <pose>25.123698979591847 -21.2433418367347 0.0 0 0 3.1416</pose>
      <static>True</static>
    </include>
    <include>
      <name>OpenRobotics/AdjTable_55</name>
      <uri>https://fuel.gazebosim.org/1.0/OpenRobotics/models/AdjTable</uri>
      <pose>25.027602040816333 -19.845586734693885 0.0 0 0 3.1416</pose>
      <static>True</static>
    </include>
    <include>
      <name>OpenRobotics/AdjTable_56</name>
      <uri>https://fuel.gazebosim.org/1.0/OpenRobotics/models/AdjTable</uri>
      <pose>25.00688775510205 -18.457219387755107 0.0 0 0 3.1416</pose>
      <static>True</static>
    </include>
    <include>
      <name>OpenRobotics/AdjTable_57</name>
      <uri>https://fuel.gazebosim.org/1.0/OpenRobotics/models/AdjTable</uri>
      <pose>24.98617346938776 -17.048137755102047 0.0 0 0 3.1416</pose>
      <static>True</static>
    </include>
    <include>
      <name>OpenRobotics/AdjTable_58</name>
      <uri>https://fuel.gazebosim.org/1.0/OpenRobotics/models/AdjTable</uri>
      <pose>24.98617346938776 -15.607959183673474 0.0 0 0 3.1416</pose>
      <static>True</static>
    </include>
    <include>
      <name>OpenRobotics/AdjTable_59</name>
      <uri>https://fuel.gazebosim.org/1.0/OpenRobotics/models/AdjTable</uri>
      <pose>25.189362244897968 -14.142500000000004 0.0 0 0 3.1416</pose>
      <static>True</static>
    </include>
    <include>
      <name>OpenRobotics/AdjTable_60</name>
      <uri>https://fuel.gazebosim.org/1.0/OpenRobotics/models/AdjTable</uri>
      <pose>25.12252551020409 -12.766607142857147 0.0 0 0 -3.1416</pose>
      <static>True</static>
    </include>
    <include>
      <name>OpenRobotics/AdjTable_61</name>
      <uri>https://fuel.gazebosim.org/1.0/OpenRobotics/models/AdjTable</uri>
      <pose>24.652142857142866 -8.73951530612245 0.0 0 0 -0.5681</pose>
      <static>True</static>
    </include>
    <include>
      <name>OpenRobotics/AdjTable_62</name>
      <uri>https://fuel.gazebosim.org/1.0/OpenRobotics/models/AdjTable</uri>
      <pose>14.75683673469388 -32.88002551020409 0.0 0 0 271.5708</pose>
      <static>True</static>
    </include>
    <include>
      <name>OpenRobotics/OfficeChairGrey</name>
      <uri>https://fuel.gazebosim.org/1.0/OpenRobotics/models/OfficeChairGrey</uri>
      <pose>15.577831632653064 -13.349693877551024 0.0 0 0 -3.1416</pose>
      <static>True</static>
    </include>
    <include>
      <name>OpenRobotics/OfficeChairGrey_2</name>
      <uri>https://fuel.gazebosim.org/1.0/OpenRobotics/models/OfficeChairGrey</uri>
      <pose>16.27321428571429 -13.307525510204085 0.0 0 0 -3.1416</pose>
      <static>True</static>
    </include>
    <include>
      <name>OpenRobotics/OfficeChairGrey_3</name>
      <uri>https://fuel.gazebosim.org/1.0/OpenRobotics/models/OfficeChairGrey</uri>
      <pose>16.94755102040817 -13.349693877551024 0.0 0 0 -3.1416</pose>
      <static>True</static>
    </include>
    <include>
      <name>OpenRobotics/OfficeChairGrey_4</name>
      <uri>https://fuel.gazebosim.org/1.0/OpenRobotics/models/OfficeChairGrey</uri>
      <pose>17.706147959183678 -13.349693877551024 0.0 0 0 -3.1416</pose>
      <static>True</static>
    </include>
    <include>
      <name>OpenRobotics/OfficeChairGrey_5</name>
      <uri>https://fuel.gazebosim.org/1.0/OpenRobotics/models/OfficeChairGrey</uri>
      <pose>19.539464285714292 -13.307525510204085 0.0 0 0 -3.1416</pose>
      <static>True</static>
    </include>
    <include>
      <name>OpenRobotics/OfficeChairGrey_6</name>
      <uri>https://fuel.gazebosim.org/1.0/OpenRobotics/models/OfficeChairGrey</uri>
      <pose>20.129489795918374 -13.286454081632655 0.0 0 0 -3.1416</pose>
      <static>True</static>
    </include>
    <include>
      <name>OpenRobotics/OfficeChairGrey_7</name>
      <uri>https://fuel.gazebosim.org/1.0/OpenRobotics/models/OfficeChairGrey</uri>
      <pose>20.914719387755106 -13.281122448979596 0.0 0 0 3.1416</pose>
      <static>True</static>
    </include>
    <include>
      <name>OpenRobotics/OfficeChairGrey_8</name>
      <uri>https://fuel.gazebosim.org/1.0/OpenRobotics/models/OfficeChairGrey</uri>
      <pose>21.60456632653062 -13.181096938775513 0.0 0 0 -3.1416</pose>
      <static>True</static>
    </include>
    <include>
      <name>OpenRobotics/OfficeChairGrey_9</name>
      <uri>https://fuel.gazebosim.org/1.0/OpenRobotics/models/OfficeChairGrey</uri>
      <pose>23.31142857142858 -13.307525510204085 0.0 0 0 -3.1416</pose>
      <static>True</static>
    </include>
    <include>
      <name>OpenRobotics/OfficeChairGrey_10</name>
      <uri>https://fuel.gazebosim.org/1.0/OpenRobotics/models/OfficeChairGrey</uri>
      <pose>23.92252551020409 -13.307525510204085 0.0 0 0 -3.1416</pose>
      <static>True</static>
    </include>
    <include>
      <name>OpenRobotics/OfficeChairGrey_11</name>
      <uri>https://fuel.gazebosim.org/1.0/OpenRobotics/models/OfficeChairGrey</uri>
      <pose>24.73816326530613 -13.2568112244898 0.0 0 0 -3.1416</pose>
      <static>True</static>
    </include>
    <include>
      <name>OpenRobotics/OfficeChairGrey_12</name>
      <uri>https://fuel.gazebosim.org/1.0/OpenRobotics/models/OfficeChairGrey</uri>
      <pose>25.376530612244906 -13.181096938775513 0.0 0 0 -3.1416</pose>
      <static>True</static>
    </include>
    <include>
      <name>OpenRobotics/OfficeChairGrey_13</name>
      <uri>https://fuel.gazebosim.org/1.0/OpenRobotics/models/OfficeChairGrey</uri>
      <pose>15.630051020408168 -14.830433673469392 0.0 0 0 -3.1416</pose>
      <static>True</static>
    </include>
    <include>
      <name>OpenRobotics/OfficeChairGrey_14</name>
      <uri>https://fuel.gazebosim.org/1.0/OpenRobotics/models/OfficeChairGrey</uri>
      <pose>16.26505102040817 -14.823469387755107 0.0 0 0 -3.1416</pose>
      <static>True</static>
    </include>
    <include>
      <name>OpenRobotics/OfficeChairGrey_15</name>
      <uri>https://fuel.gazebosim.org/1.0/OpenRobotics/models/OfficeChairGrey</uri>
      <pose>16.94755102040817 -14.803673469387759 0.0 0 0 -3.1416</pose>
      <static>True</static>
    </include>
    <include>
      <name>OpenRobotics/OfficeChairGrey_16</name>
      <uri>https://fuel.gazebosim.org/1.0/OpenRobotics/models/OfficeChairGrey</uri>
      <pose>17.811505102040822 -14.740459183673474 0.0 0 0 -3.1416</pose>
      <static>True</static>
    </include>
    <include>
      <name>OpenRobotics/OfficeChairGrey_17</name>
      <uri>https://fuel.gazebosim.org/1.0/OpenRobotics/models/OfficeChairGrey</uri>
      <pose>15.63071428571429 -16.131581632653063 0.0 0 0 3.1223</pose>
      <static>True</static>
    </include>
    <include>
      <name>OpenRobotics/OfficeChairGrey_18</name>
      <uri>https://fuel.gazebosim.org/1.0/OpenRobotics/models/OfficeChairGrey</uri>
      <pose>16.294668367346944 -16.097959183673474 0.0 0 0 -3.1416</pose>
      <static>True</static>
    </include>
    <include>
      <name>OpenRobotics/OfficeChairGrey_19</name>
      <uri>https://fuel.gazebosim.org/1.0/OpenRobotics/models/OfficeChairGrey</uri>
      <pose>17.058137755102045 -16.15198979591837 0.0 0 0 -3.1416</pose>
      <static>True</static>
    </include>
    <include>
      <name>OpenRobotics/OfficeChairGrey_20</name>
      <uri>https://fuel.gazebosim.org/1.0/OpenRobotics/models/OfficeChairGrey</uri>
      <pose>17.856530612244903 -16.098035714285718 0.0 0 0 -3.1416</pose>
      <static>True</static>
    </include>
    <include>
      <name>OpenRobotics/OfficeChairGrey_21</name>
      <uri>https://fuel.gazebosim.org/1.0/OpenRobotics/models/OfficeChairGrey</uri>
      <pose>15.558724489795924 -17.538647959183677 0.0 0 0 -3.1416</pose>
      <static>True</static>
    </include>
    <include>
      <name>OpenRobotics/OfficeChairGrey_22</name>
      <uri>https://fuel.gazebosim.org/1.0/OpenRobotics/models/OfficeChairGrey</uri>
      <pose>16.25696428571429 -17.547168367346945 0.0 0 0 -3.1416</pose>
      <static>True</static>
    </include>
    <include>
      <name>OpenRobotics/OfficeChairGrey_23</name>
      <uri>https://fuel.gazebosim.org/1.0/OpenRobotics/models/OfficeChairGrey</uri>
      <pose>17.12551020408164 -17.530127551020414 0.0 0 0 -3.1416</pose>
      <static>True</static>
    </include>
    <include>
      <name>OpenRobotics/OfficeChairGrey_24</name>
      <uri>https://fuel.gazebosim.org/1.0/OpenRobotics/models/OfficeChairGrey</uri>
      <pose>17.721556122448984 -17.487551020408166 0.0 0 0 -3.1416</pose>
      <static>True</static>
    </include>
    <include>
      <name>OpenRobotics/OfficeChairGrey_25</name>
      <uri>https://fuel.gazebosim.org/1.0/OpenRobotics/models/OfficeChairGrey</uri>
      <pose>15.655535714285719 -18.989515306122456 0.0 0 0 -3.1416</pose>
      <static>True</static>
    </include>
    <include>
      <name>OpenRobotics/OfficeChairGrey_26</name>
      <uri>https://fuel.gazebosim.org/1.0/OpenRobotics/models/OfficeChairGrey</uri>
      <pose>16.453928571428577 -19.032678571428576 0.0 0 0 -3.1416</pose>
      <static>True</static>
    </include>
    <include>
      <name>OpenRobotics/OfficeChairGrey_27</name>
      <uri>https://fuel.gazebosim.org/1.0/OpenRobotics/models/OfficeChairGrey</uri>
      <pose>17.122857142857146 -18.957142857142863 0.0 0 0 -3.1416</pose>
      <static>True</static>
    </include>
    <include>
      <name>OpenRobotics/OfficeChairGrey_28</name>
      <uri>https://fuel.gazebosim.org/1.0/OpenRobotics/models/OfficeChairGrey</uri>
      <pose>17.69821428571429 -18.98068877551021 0.0 0 0 -3.1416</pose>
      <static>True</static>
    </include>
    <include>
      <name>OpenRobotics/OfficeChairGrey_29</name>
      <uri>https://fuel.gazebosim.org/1.0/OpenRobotics/models/OfficeChairGrey</uri>
      <pose>19.415586734693882 -17.586096938775515 0.0 0 0 -3.1416</pose>
      <static>True</static>
    </include>
    <include>
      <name>OpenRobotics/OfficeChairGrey_30</name>
      <uri>https://fuel.gazebosim.org/1.0/OpenRobotics/models/OfficeChairGrey</uri>
      <pose>20.084081632653067 -17.602806122448985 0.0 0 0 -3.1416</pose>
      <static>True</static>
    </include>
    <include>
      <name>OpenRobotics/OfficeChairGrey_31</name>
      <uri>https://fuel.gazebosim.org/1.0/OpenRobotics/models/OfficeChairGrey</uri>
      <pose>19.46410714285715 -16.173571428571435 0.0 0 0 -3.1416</pose>
      <static>True</static>
    </include>
    <include>
      <name>OpenRobotics/OfficeChairGrey_32</name>
      <uri>https://fuel.gazebosim.org/1.0/OpenRobotics/models/OfficeChairGrey</uri>
      <pose>20.135484693877558 -16.08956632653062 0.0 0 0 -3.1416</pose>
      <static>True</static>
    </include>
    <include>
      <name>OpenRobotics/OfficeChairGrey_33</name>
      <uri>https://fuel.gazebosim.org/1.0/OpenRobotics/models/OfficeChairGrey</uri>
      <pose>19.44252551020409 -14.781760204081639 0.0 0 0 3.1416</pose>
      <static>True</static>
    </include>
    <include>
      <name>OpenRobotics/OfficeChairGrey_34</name>
      <uri>https://fuel.gazebosim.org/1.0/OpenRobotics/models/OfficeChairGrey</uri>
      <pose>20.16538265306123 -14.792551020408169 0.0 0 0 -3.1416</pose>
      <static>True</static>
    </include>
    <include>
      <name>OpenRobotics/OfficeChairGrey_35</name>
      <uri>https://fuel.gazebosim.org/1.0/OpenRobotics/models/OfficeChairGrey</uri>
      <pose>20.952984693877557 -14.749387755102047 0.0 0 0 -3.1416</pose>
      <static>True</static>
    </include>
    <include>
      <name>OpenRobotics/OfficeChairGrey_36</name>
      <uri>https://fuel.gazebosim.org/1.0/OpenRobotics/models/OfficeChairGrey</uri>
      <pose>21.647015306122455 -14.788290816326535 0.0 0 0 3.1416</pose>
      <static>True</static>
    </include>
    <include>
      <name>OpenRobotics/OfficeChairGrey_37</name>
      <uri>https://fuel.gazebosim.org/1.0/OpenRobotics/models/OfficeChairGrey</uri>
      <pose>21.547423469387763 -16.064362244897964 0.0 0 0 -3.1416</pose>
      <static>True</static>
    </include>
    <include>
      <name>OpenRobotics/OfficeChairGrey_38</name>
      <uri>https://fuel.gazebosim.org/1.0/OpenRobotics/models/OfficeChairGrey</uri>
      <pose>20.917091836734702 -16.140000000000004 0.0 0 0 -3.1416</pose>
      <static>True</static>
    </include>
    <include>
      <name>OpenRobotics/OfficeChairGrey_39</name>
      <uri>https://fuel.gazebosim.org/1.0/OpenRobotics/models/OfficeChairGrey</uri>
      <pose>21.093265306122454 -17.619311224489802 0.0 0 0 -3.1416</pose>
      <static>True</static>
    </include>
    <include>
      <name>OpenRobotics/OfficeChairGrey_40</name>
      <uri>https://fuel.gazebosim.org/1.0/OpenRobotics/models/OfficeChairGrey</uri>
      <pose>21.82691326530613 -17.56535714285715 0.0 0 0 -3.1416</pose>
      <static>True</static>
    </include>
    <include>
      <name>OpenRobotics/OfficeChairGrey_41</name>
      <uri>https://fuel.gazebosim.org/1.0/OpenRobotics/models/OfficeChairGrey</uri>
      <pose>23.25206632653062 -14.607193877551024 0.0 0 0 -3.1416</pose>
      <static>True</static>
    </include>
    <include>
      <name>OpenRobotics/OfficeChairGrey_42</name>
      <uri>https://fuel.gazebosim.org/1.0/OpenRobotics/models/OfficeChairGrey</uri>
      <pose>23.83244897959184 -14.680663265306126 0.0 0 0 -3.1416</pose>
      <static>True</static>
    </include>
    <include>
      <name>OpenRobotics/OfficeChairGrey_43</name>
      <uri>https://fuel.gazebosim.org/1.0/OpenRobotics/models/OfficeChairGrey</uri>
      <pose>24.728698979591844 -14.680663265306126 0.0 0 0 -3.1416</pose>
      <static>True</static>
    </include>
    <include>
      <name>OpenRobotics/OfficeChairGrey_44</name>
      <uri>https://fuel.gazebosim.org/1.0/OpenRobotics/models/OfficeChairGrey</uri>
      <pose>25.353112244897968 -14.658622448979598 0.0 0 0 -3.1416</pose>
      <static>True</static>
    </include>
    <include>
      <name>OpenRobotics/OfficeChairGrey_45</name>
      <uri>https://fuel.gazebosim.org/1.0/OpenRobotics/models/OfficeChairGrey</uri>
      <pose>23.251071428571436 -16.184362244897965 0.0 0 0 3.1416</pose>
      <static>True</static>
    </include>
    <include>
      <name>OpenRobotics/OfficeChairGrey_46</name>
      <uri>https://fuel.gazebosim.org/1.0/OpenRobotics/models/OfficeChairGrey</uri>
      <pose>24.008750000000006 -16.171964285714292 0.0 0 0 -3.1416</pose>
      <static>True</static>
    </include>
    <include>
      <name>OpenRobotics/OfficeChairGrey_47</name>
      <uri>https://fuel.gazebosim.org/1.0/OpenRobotics/models/OfficeChairGrey</uri>
      <pose>24.78313775510205 -16.14119897959184 0.0 0 0 -3.1416</pose>
      <static>True</static>
    </include>
    <include>
      <name>OpenRobotics/OfficeChairGrey_48</name>
      <uri>https://fuel.gazebosim.org/1.0/OpenRobotics/models/OfficeChairGrey</uri>
      <pose>25.48441326530613 -16.195127551020413 0.0 0 0 -3.1416</pose>
      <static>True</static>
    </include>
    <include>
      <name>OpenRobotics/OfficeChairGrey_49</name>
      <uri>https://fuel.gazebosim.org/1.0/OpenRobotics/models/OfficeChairGrey</uri>
      <pose>25.356556122448985 -17.658010204081638 0.0 0 0 -3.1233</pose>
      <static>True</static>
    </include>
    <include>
      <name>OpenRobotics/OfficeChairGrey_50</name>
      <uri>https://fuel.gazebosim.org/1.0/OpenRobotics/models/OfficeChairGrey</uri>
      <pose>24.675229591836743 -17.57614795918368 0.0 0 0 3.1359</pose>
      <static>True</static>
    </include>
    <include>
      <name>OpenRobotics/OfficeChairGrey_51</name>
      <uri>https://fuel.gazebosim.org/1.0/OpenRobotics/models/OfficeChairGrey</uri>
      <pose>23.86604591836735 -17.619311224489802 0.0 0 0 -3.123</pose>
      <static>True</static>
    </include>
    <include>
      <name>OpenRobotics/OfficeChairGrey_52</name>
      <uri>https://fuel.gazebosim.org/1.0/OpenRobotics/models/OfficeChairGrey</uri>
      <pose>23.240280612244906 -17.59772959183674 0.0 0 0 3.1416</pose>
      <static>True</static>
    </include>
    <include>
      <name>OpenRobotics/OfficeChairGrey_53</name>
      <uri>https://fuel.gazebosim.org/1.0/OpenRobotics/models/OfficeChairGrey</uri>
      <pose>23.30502551020409 -19.021887755102046 0.0 0 0 -3.1416</pose>
      <static>True</static>
    </include>
    <include>
      <name>OpenRobotics/OfficeChairGrey_54</name>
      <uri>https://fuel.gazebosim.org/1.0/OpenRobotics/models/OfficeChairGrey</uri>
      <pose>24.00630102040817 -18.978724489795923 0.0 0 0 -3.1416</pose>
      <static>True</static>
    </include>
    <include>
      <name>OpenRobotics/OfficeChairGrey_55</name>
      <uri>https://fuel.gazebosim.org/1.0/OpenRobotics/models/OfficeChairGrey</uri>
      <pose>24.697168367346947 -19.02642857142858 0.0 0 0 -3.1416</pose>
      <static>True</static>
    </include>
    <include>
      <name>OpenRobotics/OfficeChairGrey_56</name>
      <uri>https://fuel.gazebosim.org/1.0/OpenRobotics/models/OfficeChairGrey</uri>
      <pose>25.426020408163275 -18.992984693877556 0.0 0 0 -3.1416</pose>
      <static>True</static>
    </include>
    <include>
      <name>OpenRobotics/OfficeChairGrey_57</name>
      <uri>https://fuel.gazebosim.org/1.0/OpenRobotics/models/OfficeChairGrey</uri>
      <pose>23.232755102040823 -20.410586734693883 0.0 0 0 3.1416</pose>
      <static>True</static>
    </include>
    <include>
      <name>OpenRobotics/OfficeChairGrey_58</name>
      <uri>https://fuel.gazebosim.org/1.0/OpenRobotics/models/OfficeChairGrey</uri>
      <pose>23.841250000000006 -20.377142857142864 0.0 0 0 -3.1416</pose>
      <static>True</static>
    </include>
    <include>
      <name>OpenRobotics/OfficeChairGrey_59</name>
      <uri>https://fuel.gazebosim.org/1.0/OpenRobotics/models/OfficeChairGrey</uri>
      <pose>24.729183673469397 -20.38130102040817 0.0 0 0 -3.1416</pose>
      <static>True</static>
    </include>
    <include>
      <name>OpenRobotics/OfficeChairGrey_60</name>
      <uri>https://fuel.gazebosim.org/1.0/OpenRobotics/models/OfficeChairGrey</uri>
      <pose>25.352474489795927 -20.36377551020409 0.0 0 0 -3.1416</pose>
      <static>True</static>
    </include>
    <include>
      <name>OpenRobotics/OfficeChairGrey_61</name>
      <uri>https://fuel.gazebosim.org/1.0/OpenRobotics/models/OfficeChairGrey</uri>
      <pose>25.33908163265307 -21.814795918367352 0.0 0 0 -3.1416</pose>
      <static>True</static>
    </include>
    <include>
      <name>OpenRobotics/OfficeChairGrey_62</name>
      <uri>https://fuel.gazebosim.org/1.0/OpenRobotics/models/OfficeChairGrey</uri>
      <pose>24.737270408163273 -21.79474489795919 0.0 0 0 -3.1416</pose>
      <static>True</static>
    </include>
    <include>
      <name>OpenRobotics/OfficeChairGrey_63</name>
      <uri>https://fuel.gazebosim.org/1.0/OpenRobotics/models/OfficeChairGrey</uri>
      <pose>23.799464285714294 -21.787704081632658 0.0 0 0 -3.1416</pose>
      <static>True</static>
    </include>
    <include>
      <name>OpenRobotics/OfficeChairGrey_64</name>
      <uri>https://fuel.gazebosim.org/1.0/OpenRobotics/models/OfficeChairGrey</uri>
      <pose>23.242576530612254 -21.77558673469388 0.0 0 0 3.1416</pose>
      <static>True</static>
    </include>
    <include>
      <name>OpenRobotics/OfficeChairGrey_65</name>
      <uri>https://fuel.gazebosim.org/1.0/OpenRobotics/models/OfficeChairGrey</uri>
      <pose>23.197117346938782 -23.19727040816327 0.0 0 0 -3.1416</pose>
      <static>True</static>
    </include>
    <include>
      <name>OpenRobotics/OfficeChairGrey_66</name>
      <uri>https://fuel.gazebosim.org/1.0/OpenRobotics/models/OfficeChairGrey</uri>
      <pose>23.908418367346947 -23.20413265306123 0.0 0 0 -3.1416</pose>
      <static>True</static>
    </include>
    <include>
      <name>OpenRobotics/OfficeChairGrey_67</name>
      <uri>https://fuel.gazebosim.org/1.0/OpenRobotics/models/OfficeChairGrey</uri>
      <pose>24.772346938775517 -23.17568877551021 0.0 0 0 3.1416</pose>
      <static>True</static>
    </include>
    <include>
      <name>OpenRobotics/OfficeChairGrey_68</name>
      <uri>https://fuel.gazebosim.org/1.0/OpenRobotics/models/OfficeChairGrey</uri>
      <pose>25.391454081632663 -23.222295918367355 0.0 0 0 -3.1416</pose>
      <static>True</static>
    </include>
    <include>
      <name>OpenRobotics/OfficeChairGrey_69</name>
      <uri>https://fuel.gazebosim.org/1.0/OpenRobotics/models/OfficeChairGrey</uri>
      <pose>25.361198979591844 -24.644795918367354 0.0 0 0 -3.1416</pose>
      <static>True</static>
    </include>
    <include>
      <name>OpenRobotics/OfficeChairGrey_70</name>
      <uri>https://fuel.gazebosim.org/1.0/OpenRobotics/models/OfficeChairGrey</uri>
      <pose>24.739974489795927 -24.610637755102047 0.0 0 0 -3.1416</pose>
      <static>True</static>
    </include>
    <include>
      <name>OpenRobotics/OfficeChairGrey_71</name>
      <uri>https://fuel.gazebosim.org/1.0/OpenRobotics/models/OfficeChairGrey</uri>
      <pose>23.860000000000007 -24.67505102040817 0.0 0 0 -3.1416</pose>
      <static>True</static>
    </include>
    <include>
      <name>OpenRobotics/OfficeChairGrey_72</name>
      <uri>https://fuel.gazebosim.org/1.0/OpenRobotics/models/OfficeChairGrey</uri>
      <pose>15.472142857142863 -20.38130102040817 0.0 0 0 -3.1416</pose>
      <static>True</static>
    </include>
    <include>
      <name>OpenRobotics/OfficeChairGrey_73</name>
      <uri>https://fuel.gazebosim.org/1.0/OpenRobotics/models/OfficeChairGrey</uri>
      <pose>16.356836734693882 -20.34895408163266 0.0 0 0 -3.1416</pose>
      <static>True</static>
    </include>
    <include>
      <name>OpenRobotics/OfficeChairGrey_74</name>
      <uri>https://fuel.gazebosim.org/1.0/OpenRobotics/models/OfficeChairGrey</uri>
      <pose>17.122857142857146 -20.33816326530613 0.0 0 0 -3.1416</pose>
      <static>True</static>
    </include>
    <include>
      <name>OpenRobotics/OfficeChairGrey_75</name>
      <uri>https://fuel.gazebosim.org/1.0/OpenRobotics/models/OfficeChairGrey</uri>
      <pose>17.7758418367347 -20.409642857142863 0.0 0 0 3.1416</pose>
      <static>True</static>
    </include>
    <include>
      <name>OpenRobotics/OfficeChairGrey_76</name>
      <uri>https://fuel.gazebosim.org/1.0/OpenRobotics/models/OfficeChairGrey</uri>
      <pose>15.547653061224493 -21.827040816326537 0.0 0 0 -3.1416</pose>
      <static>True</static>
    </include>
    <include>
      <name>OpenRobotics/OfficeChairGrey_77</name>
      <uri>https://fuel.gazebosim.org/1.0/OpenRobotics/models/OfficeChairGrey</uri>
      <pose>16.2190306122449 -21.821377551020415 0.0 0 0 -3.1416</pose>
      <static>True</static>
    </include>
    <include>
      <name>OpenRobotics/OfficeChairGrey_78</name>
      <uri>https://fuel.gazebosim.org/1.0/OpenRobotics/models/OfficeChairGrey</uri>
      <pose>17.15522959183674 -21.816250000000007 0.0 0 0 3.1416</pose>
      <static>True</static>
    </include>
    <include>
      <name>OpenRobotics/OfficeChairGrey_79</name>
      <uri>https://fuel.gazebosim.org/1.0/OpenRobotics/models/OfficeChairGrey</uri>
      <pose>17.79066326530613 -21.82977040816327 0.0 0 0 3.1416</pose>
      <static>True</static>
    </include>
    <include>
      <name>OpenRobotics/OfficeChairGrey_80</name>
      <uri>https://fuel.gazebosim.org/1.0/OpenRobotics/models/OfficeChairGrey</uri>
      <pose>17.773852040816333 -23.11566326530613 0.0 0 0 -3.1416</pose>
      <static>True</static>
    </include>
    <include>
      <name>OpenRobotics/OfficeChairGrey_81</name>
      <uri>https://fuel.gazebosim.org/1.0/OpenRobotics/models/OfficeChairGrey</uri>
      <pose>17.036556122448985 -23.18647959183674 0.0 0 0 -3.1416</pose>
      <static>True</static>
    </include>
    <include>
      <name>OpenRobotics/OfficeChairGrey_82</name>
      <uri>https://fuel.gazebosim.org/1.0/OpenRobotics/models/OfficeChairGrey</uri>
      <pose>16.32446428571429 -23.132525510204086 0.0 0 0 -3.1416</pose>
      <static>True</static>
    </include>
    <include>
      <name>OpenRobotics/OfficeChairGrey_83</name>
      <uri>https://fuel.gazebosim.org/1.0/OpenRobotics/models/OfficeChairGrey</uri>
      <pose>15.613903061224496 -23.166071428571435 0.0 0 0 -3.1416</pose>
      <static>True</static>
    </include>
    <include>
      <name>OpenRobotics/OfficeChairGrey_84</name>
      <uri>https://fuel.gazebosim.org/1.0/OpenRobotics/models/OfficeChairGrey</uri>
      <pose>15.706377551020415 -24.602423469387762 0.0 0 0 3.1416</pose>
      <static>True</static>
    </include>
    <include>
      <name>OpenRobotics/OfficeChairGrey_85</name>
      <uri>https://fuel.gazebosim.org/1.0/OpenRobotics/models/OfficeChairGrey</uri>
      <pose>16.263265306122452 -24.602423469387762 0.0 0 0 -3.1416</pose>
      <static>True</static>
    </include>
    <include>
      <name>OpenRobotics/OfficeChairGrey_86</name>
      <uri>https://fuel.gazebosim.org/1.0/OpenRobotics/models/OfficeChairGrey</uri>
      <pose>17.122831632653067 -24.620586734693884 0.0 0 0 -3.1416</pose>
      <static>True</static>
    </include>
    <include>
      <name>OpenRobotics/OfficeChairGrey_87</name>
      <uri>https://fuel.gazebosim.org/1.0/OpenRobotics/models/OfficeChairGrey</uri>
      <pose>17.776556122448984 -24.58426020408164 0.0 0 0 -3.1416</pose>
      <static>True</static>
    </include>
    <include>
      <name>OpenRobotics/OfficeChairGrey_88</name>
      <uri>https://fuel.gazebosim.org/1.0/OpenRobotics/models/OfficeChairGrey</uri>
      <pose>19.501709183673476 -24.58426020408164 0.0 0 0 -3.1416</pose>
      <static>True</static>
    </include>
    <include>
      <name>OpenRobotics/OfficeChairGrey_89</name>
      <uri>https://fuel.gazebosim.org/1.0/OpenRobotics/models/OfficeChairGrey</uri>
      <pose>20.18696428571429 -24.599846938775517 0.0 0 0 3.1269</pose>
      <static>True</static>
    </include>
    <include>
      <name>OpenRobotics/OfficeChairGrey_90</name>
      <uri>https://fuel.gazebosim.org/1.0/OpenRobotics/models/OfficeChairGrey</uri>
      <pose>20.966581632653067 -24.59030612244899 0.0 0 0 -3.1416</pose>
      <static>True</static>
    </include>
    <include>
      <name>OpenRobotics/OfficeChairGrey_91</name>
      <uri>https://fuel.gazebosim.org/1.0/OpenRobotics/models/OfficeChairGrey</uri>
      <pose>21.632704081632657 -24.610637755102047 0.0 0 0 3.1416</pose>
      <static>True</static>
    </include>
    <include>
      <name>OpenRobotics/OfficeChairGrey_92</name>
      <uri>https://fuel.gazebosim.org/1.0/OpenRobotics/models/OfficeChairGrey</uri>
      <pose>21.61428571428572 -23.167806122448987 0.0 0 0 -3.1416</pose>
      <static>True</static>
    </include>
    <include>
      <name>OpenRobotics/OfficeChairGrey_93</name>
      <uri>https://fuel.gazebosim.org/1.0/OpenRobotics/models/OfficeChairGrey</uri>
      <pose>21.021071428571435 -23.149668367346944 0.0 0 0 -3.1416</pose>
      <static>True</static>
    </include>
    <include>
      <name>OpenRobotics/OfficeChairGrey_94</name>
      <uri>https://fuel.gazebosim.org/1.0/OpenRobotics/models/OfficeChairGrey</uri>
      <pose>20.070714285714292 -23.179923469387763 0.0 0 0 -3.1416</pose>
      <static>True</static>
    </include>
    <include>
      <name>OpenRobotics/OfficeChairGrey_95</name>
      <uri>https://fuel.gazebosim.org/1.0/OpenRobotics/models/OfficeChairGrey</uri>
      <pose>19.356198979591845 -23.15410714285715 0.0 0 0 -3.1416</pose>
      <static>True</static>
    </include>
    <include>
      <name>OpenRobotics/OfficeChairGrey_96</name>
      <uri>https://fuel.gazebosim.org/1.0/OpenRobotics/models/OfficeChairGrey</uri>
      <pose>19.485688775510212 -21.85941326530613 0.0 0 0 -3.1416</pose>
      <static>True</static>
    </include>
    <include>
      <name>OpenRobotics/OfficeChairGrey_97</name>
      <uri>https://fuel.gazebosim.org/1.0/OpenRobotics/models/OfficeChairGrey</uri>
      <pose>20.185918367346947 -21.787755102040823 0.0 0 0 -3.1416</pose>
      <static>True</static>
    </include>
    <include>
      <name>OpenRobotics/OfficeChairGrey_98</name>
      <uri>https://fuel.gazebosim.org/1.0/OpenRobotics/models/OfficeChairGrey</uri>
      <pose>21.05010204081633 -21.751530612244903 0.0 0 0 3.1416</pose>
      <static>True</static>
    </include>
    <include>
      <name>OpenRobotics/OfficeChairGrey_99</name>
      <uri>https://fuel.gazebosim.org/1.0/OpenRobotics/models/OfficeChairGrey</uri>
      <pose>21.70711734693878 -21.779362244897964 0.0 0 0 -3.1416</pose>
      <static>True</static>
    </include>
    <include>
      <name>OpenRobotics/OfficeChairGrey_100</name>
      <uri>https://fuel.gazebosim.org/1.0/OpenRobotics/models/OfficeChairGrey</uri>
      <pose>21.913214285714293 -20.467627551020414 0.0 0 0 -3.1416</pose>
      <static>True</static>
    </include>
    <include>
      <name>OpenRobotics/OfficeChairGrey_101</name>
      <uri>https://fuel.gazebosim.org/1.0/OpenRobotics/models/OfficeChairGrey</uri>
      <pose>20.931428571428576 -20.3920918367347 0.0 0 0 -3.1416</pose>
      <static>True</static>
    </include>
    <include>
      <name>OpenRobotics/OfficeChairGrey_102</name>
      <uri>https://fuel.gazebosim.org/1.0/OpenRobotics/models/OfficeChairGrey</uri>
      <pose>20.116147959183678 -20.43801020408164 0.0 0 0 -3.1401</pose>
      <static>True</static>
    </include>
    <include>
      <name>OpenRobotics/OfficeChairGrey_103</name>
      <uri>https://fuel.gazebosim.org/1.0/OpenRobotics/models/OfficeChairGrey</uri>
      <pose>19.45581632653062 -20.37520408163266 0.0 0 0 -3.1416</pose>
      <static>True</static>
    </include>
    <include>
      <name>OpenRobotics/OfficeChairGrey_104</name>
      <uri>https://fuel.gazebosim.org/1.0/OpenRobotics/models/OfficeChairGrey</uri>
      <pose>19.615153061224497 -18.967933673469393 0.0 0 0 -3.1416</pose>
      <static>True</static>
    </include>
    <include>
      <name>OpenRobotics/OfficeChairGrey_105</name>
      <uri>https://fuel.gazebosim.org/1.0/OpenRobotics/models/OfficeChairGrey</uri>
      <pose>20.316428571428577 -18.924770408163273 0.0 0 0 -3.1416</pose>
      <static>True</static>
    </include>
    <include>
      <name>OpenRobotics/OfficeChairGrey_106</name>
      <uri>https://fuel.gazebosim.org/1.0/OpenRobotics/models/OfficeChairGrey</uri>
      <pose>21.01772959183674 -19.000306122448986 0.0 0 0 3.1416</pose>
      <static>True</static>
    </include>
    <include>
      <name>OpenRobotics/OfficeChairGrey_107</name>
      <uri>https://fuel.gazebosim.org/1.0/OpenRobotics/models/OfficeChairGrey</uri>
      <pose>21.740586734693885 -18.957142857142863 0.0 0 0 -3.1416</pose>
      <static>True</static>
    </include>
    <include>
      <name>OpenRobotics/OfficeChairGrey_108</name>
      <uri>https://fuel.gazebosim.org/1.0/OpenRobotics/models/OfficeChairGrey</uri>
      <pose>19.45864795918368 -11.86760204081633 0.0 0 0 -3.1416</pose>
      <static>True</static>
    </include>
    <include>
      <name>OpenRobotics/OfficeChairGrey_109</name>
      <uri>https://fuel.gazebosim.org/1.0/OpenRobotics/models/OfficeChairGrey</uri>
      <pose>20.122806122448985 -11.816530612244902 0.0 0 0 -3.1416</pose>
      <static>True</static>
    </include>
    <include>
      <name>OpenRobotics/OfficeChairGrey_110</name>
      <uri>https://fuel.gazebosim.org/1.0/OpenRobotics/models/OfficeChairGrey</uri>
      <pose>20.914719387755106 -11.90165816326531 0.0 0 0 -3.1416</pose>
      <static>True</static>
    </include>
    <include>
      <name>OpenRobotics/OfficeChairGrey_111</name>
      <uri>https://fuel.gazebosim.org/1.0/OpenRobotics/models/OfficeChairGrey</uri>
      <pose>21.564234693877555 -11.887346938775513 0.0 0 0 3.1416</pose>
      <static>True</static>
    </include>
    <include>
      <name>OpenRobotics/OfficeChairGrey_112</name>
      <uri>https://fuel.gazebosim.org/1.0/OpenRobotics/models/OfficeChairGrey</uri>
      <pose>23.30502551020409 -11.901071428571433 0.0 0 0 -3.1416</pose>
      <static>True</static>
    </include>
    <include>
      <name>OpenRobotics/OfficeChairGrey_113</name>
      <uri>https://fuel.gazebosim.org/1.0/OpenRobotics/models/OfficeChairGrey</uri>
      <pose>23.958290816326535 -11.919897959183677 0.0 0 0 -3.1416</pose>
      <static>True</static>
    </include>
    <include>
      <name>OpenRobotics/OfficeChairGrey_114</name>
      <uri>https://fuel.gazebosim.org/1.0/OpenRobotics/models/OfficeChairGrey</uri>
      <pose>24.844005102040825 -11.936607142857147 0.0 0 0 3.1416</pose>
      <static>True</static>
    </include>
    <include>
      <name>OpenRobotics/OfficeChairGrey_115</name>
      <uri>https://fuel.gazebosim.org/1.0/OpenRobotics/models/OfficeChairGrey</uri>
      <pose>25.401045918367355 -11.903188775510207 0.0 0 0 -3.1416</pose>
      <static>True</static>
    </include>
    <include>
      <name>OpenRobotics/OfficeChairGrey_116</name>
      <uri>https://fuel.gazebosim.org/1.0/OpenRobotics/models/OfficeChairGrey</uri>
      <pose>15.633979591836738 -11.922653061224493 0.0 0 0 -3.1416</pose>
      <static>True</static>
    </include>
    <include>
      <name>OpenRobotics/OfficeChairGrey_117</name>
      <uri>https://fuel.gazebosim.org/1.0/OpenRobotics/models/OfficeChairGrey</uri>
      <pose>16.2358418367347 -11.912576530612249 0.0 0 0 -3.1416</pose>
      <static>True</static>
    </include>
    <include>
      <name>OpenRobotics/OfficeChairGrey_118</name>
      <uri>https://fuel.gazebosim.org/1.0/OpenRobotics/models/OfficeChairGrey</uri>
      <pose>17.058137755102045 -11.911862244897963 0.0 0 0 -3.1416</pose>
      <static>True</static>
    </include>
    <include>
      <name>OpenRobotics/OfficeChairGrey_119</name>
      <uri>https://fuel.gazebosim.org/1.0/OpenRobotics/models/OfficeChairGrey</uri>
      <pose>17.716428571428576 -11.878826530612248 0.0 0 0 -3.1416</pose>
      <static>True</static>
    </include>
    <include>
      <name>OpenRobotics/OfficeChairGrey_120</name>
      <uri>https://fuel.gazebosim.org/1.0/OpenRobotics/models/OfficeChairGrey</uri>
      <pose>24.727040816326536 -8.140331632653064 0.0 0 0 -0.588</pose>
      <static>True</static>
    </include>
    <include>
      <name>OpenRobotics/OfficeChairGrey_121</name>
      <uri>https://fuel.gazebosim.org/1.0/OpenRobotics/models/OfficeChairGrey</uri>
      <pose>25.320867346938783 -8.429209183673471 0.0 0 0 -0.58</pose>
      <static>True</static>
    </include>
    <include>
      <name>OpenRobotics/OfficeChairGrey_122</name>
      <uri>https://fuel.gazebosim.org/1.0/OpenRobotics/models/OfficeChairGrey</uri>
      <pose>23.236530612244902 -24.687168367346946 0.0 0 0 -3.1416</pose>
      <static>True</static>
    </include>
    <include>
      <name>tinyRobot1</name>
      <uri>model://TinyRobot</uri>
      <pose>14.76336734693878 -7.130178571428573 0.0 0 0 -0.18554897451932328</pose>
    </include>
    <include>
      <name>tinyRobot2</name>
      <uri>model://TinyRobot</uri>
      <pose>26.390102040816334 -43.52367346938777 0.0 0 0 -1.5707963267948966</pose>
    </include>
    <model name="door1">
      <pose>18.859094387755107 -31.709056122448985 0.0 0 0 3.141592653589793</pose>
      <link name="right">
        <pose>0.7511288265306124 0 1.11 0 0 0</pose>
        <visual name="right_visual">
          <geometry>
            <box>
              <size>1.4922576530612248 0.03 2.2</size>
            </box>
          </geometry>
          <material>
            <ambient>0.5 0.25 0 0.6</ambient>
            <diffuse>0.5 0.25 0 0.6</diffuse>
            <pbr>
              <metal>
                <metalness>0.0</metalness>
              </metal>
            </pbr>
          </material>
        </visual>
        <collision name="right_collision">
          <geometry>
            <box>
              <size>1.4922576530612248 0.03 2.2</size>
            </box>
          </geometry>
          <surface>
            <contact>
              <collide_bitmask>0x02</collide_bitmask>
            </contact>
          </surface>
        </collision>
        <inertial>
          <mass>50.0</mass>
          <inertia>
            <ixx>20.17041666666667</ixx>
            <iyy>29.445137096332484</iyy>
            <izz>9.282220429665813</izz>
          </inertia>
        </inertial>
      </link>
      <joint name="right_joint" type="revolute">
        <parent>world</parent>
        <child>right</child>
        <axis>
          <xyz>0 0 -1</xyz>
          <limit>
            <lower>0</lower>
            <upper>1.57</upper>
          </limit>
        </axis>
        <pose>0.7511288265306124 0 0 0 0 0</pose>
      </joint>
      <link name="left">
        <pose>-0.7511288265306124 0 1.11 0 0 0</pose>
        <visual name="left_visual">
          <geometry>
            <box>
              <size>1.4922576530612248 0.03 2.2</size>
            </box>
          </geometry>
          <material>
            <ambient>0.5 0.25 0 0.6</ambient>
            <diffuse>0.5 0.25 0 0.6</diffuse>
            <pbr>
              <metal>
                <metalness>0.0</metalness>
              </metal>
            </pbr>
          </material>
        </visual>
        <collision name="left_collision">
          <geometry>
            <box>
              <size>1.4922576530612248 0.03 2.2</size>
            </box>
          </geometry>
          <surface>
            <contact>
              <collide_bitmask>0x02</collide_bitmask>
            </contact>
          </surface>
        </collision>
        <inertial>
          <mass>50.0</mass>
          <inertia>
            <ixx>20.17041666666667</ixx>
            <iyy>29.445137096332484</iyy>
            <izz>9.282220429665813</izz>
          </inertia>
        </inertial>
      </link>
      <joint name="left_joint" type="revolute">
        <parent>world</parent>
        <child>left</child>
        <axis>
          <xyz>0 0 -1</xyz>
          <limit>
            <lower>-1.57</lower>
            <upper>0</upper>
          </limit>
        </axis>
        <pose>-0.7511288265306124 0 0 0 0 0</pose>
      </joint>
      <plugin name="register_component" filename="libregister_component.so">
        <component name="Door">
          <v_max_door>0.5</v_max_door>
          <a_max_door>0.3</a_max_door>
          <a_nom_door>0.15</a_nom_door>
          <dx_min_door>0.01</dx_min_door>
          <f_max_door>500.0</f_max_door>
          <ros_interface>true</ros_interface>
          <door name="door1" type="DoubleSwingDoor" left_joint_name="left_joint" right_joint_name="right_joint" />
        </component>
      </plugin>
    </model>
    <model name="door2">
      <pose>17.345918367346943 -35.05772959183675 0.0 0 0 1.5707963267948966</pose>
      <link name="right">
        <pose>0 0 1.11 0 0 0</pose>
        <visual name="right_visual">
          <geometry>
            <box>
              <size>0.9003061224489792 0.03 2.2</size>
            </box>
          </geometry>
          <material>
            <ambient>0.5 0.25 0 0.6</ambient>
            <diffuse>0.5 0.25 0 0.6</diffuse>
            <pbr>
              <metal>
                <metalness>0.0</metalness>
              </metal>
            </pbr>
          </material>
        </visual>
        <collision name="right_collision">
          <geometry>
            <box>
              <size>0.9003061224489792 0.03 2.2</size>
            </box>
          </geometry>
          <surface>
            <contact>
              <collide_bitmask>0x02</collide_bitmask>
            </contact>
          </surface>
        </collision>
        <inertial>
          <mass>50.0</mass>
          <inertia>
            <ixx>20.17041666666667</ixx>
            <iyy>23.54396297549632</iyy>
            <izz>3.381046308829652</izz>
          </inertia>
        </inertial>
      </link>
      <joint name="right_joint" type="revolute">
        <parent>world</parent>
        <child>right</child>
        <axis>
          <xyz>0 0 1</xyz>
          <limit>
            <lower>0</lower>
            <upper>1.57</upper>
          </limit>
        </axis>
        <pose>0.4551530612244896 0 0 0 0 0</pose>
      </joint>
      <plugin name="register_component" filename="libregister_component.so">
        <component name="Door">
          <v_max_door>0.5</v_max_door>
          <a_max_door>0.3</a_max_door>
          <a_nom_door>0.15</a_nom_door>
          <dx_min_door>0.01</dx_min_door>
          <f_max_door>500.0</f_max_door>
          <ros_interface>true</ros_interface>
          <door name="door2" type="SwingDoor" left_joint_name="empty_joint" right_joint_name="right_joint" />
        </component>
      </plugin>
    </model>
    <model name="door3">
      <pose>23.58721938775511 -35.04910714285715 0.0 0 0 1.5707963267948966</pose>
      <link name="right">
        <pose>0 0 1.11 0 0 0</pose>
        <visual name="right_visual">
          <geometry>
            <box>
              <size>0.9289795918367341 0.03 2.2</size>
            </box>
          </geometry>
          <material>
            <ambient>0.5 0.25 0 0.6</ambient>
            <diffuse>0.5 0.25 0 0.6</diffuse>
            <pbr>
              <metal>
                <metalness>0.0</metalness>
              </metal>
            </pbr>
          </material>
        </visual>
        <collision name="right_collision">
          <geometry>
            <box>
              <size>0.9289795918367341 0.03 2.2</size>
            </box>
          </geometry>
          <surface>
            <contact>
              <collide_bitmask>0x02</collide_bitmask>
            </contact>
          </surface>
        </collision>
        <inertial>
          <mass>50.0</mass>
          <inertia>
            <ixx>20.17041666666667</ixx>
            <iyy>23.762512841871445</iyy>
            <izz>3.599596175204771</izz>
          </inertia>
        </inertial>
      </link>
      <joint name="right_joint" type="prismatic">
        <parent>world</parent>
        <child>right</child>
        <axis>
          <xyz>1 0 0</xyz>
          <limit>
            <lower>0.0</lower>
            <upper>0.9389795918367341</upper>
            <effort>500.0</effort>
          </limit>
        </axis>
      </joint>
      <plugin name="register_component" filename="libregister_component.so">
        <component name="Door">
          <v_max_door>0.2</v_max_door>
          <a_max_door>0.2</a_max_door>
          <a_nom_door>0.08</a_nom_door>
          <dx_min_door>0.001</dx_min_door>
          <f_max_door>100.0</f_max_door>
          <ros_interface>true</ros_interface>
          <door name="door3" type="SlidingDoor" left_joint_name="empty_joint" right_joint_name="right_joint" />
        </component>
      </plugin>
    </model>
    <model name="door4">
      <pose>16.988928571428577 -43.36737244897961 0.0 0 0 1.5707963267948966</pose>
      <link name="right">
        <pose>0.338354591836735 0 1.11 0 0 0</pose>
        <visual name="right_visual">
          <geometry>
            <box>
              <size>0.66670918367347 0.03 2.2</size>
            </box>
          </geometry>
          <material>
            <ambient>0.5 0.25 0 0.6</ambient>
            <diffuse>0.5 0.25 0 0.6</diffuse>
            <pbr>
              <metal>
                <metalness>0.0</metalness>
              </metal>
            </pbr>
          </material>
        </visual>
        <collision name="right_collision">
          <geometry>
            <box>
              <size>0.66670918367347 0.03 2.2</size>
            </box>
          </geometry>
          <surface>
            <contact>
              <collide_bitmask>0x02</collide_bitmask>
            </contact>
          </surface>
        </collision>
        <inertial>
          <mass>50.0</mass>
          <inertia>
            <ixx>20.17041666666667</ixx>
            <iyy>22.01875473164394</iyy>
            <izz>1.8558380649772699</izz>
          </inertia>
        </inertial>
      </link>
      <joint name="right_joint" type="revolute">
        <parent>world</parent>
        <child>right</child>
        <axis>
          <xyz>0 0 1</xyz>
          <limit>
            <lower>0</lower>
            <upper>1.57</upper>
          </limit>
        </axis>
        <pose>0.338354591836735 0 0 0 0 0</pose>
      </joint>
      <link name="left">
        <pose>-0.338354591836735 0 1.11 0 0 0</pose>
        <visual name="left_visual">
          <geometry>
            <box>
              <size>0.66670918367347 0.03 2.2</size>
            </box>
          </geometry>
          <material>
            <ambient>0.5 0.25 0 0.6</ambient>
            <diffuse>0.5 0.25 0 0.6</diffuse>
            <pbr>
              <metal>
                <metalness>0.0</metalness>
              </metal>
            </pbr>
          </material>
        </visual>
        <collision name="left_collision">
          <geometry>
            <box>
              <size>0.66670918367347 0.03 2.2</size>
            </box>
          </geometry>
          <surface>
            <contact>
              <collide_bitmask>0x02</collide_bitmask>
            </contact>
          </surface>
        </collision>
        <inertial>
          <mass>50.0</mass>
          <inertia>
            <ixx>20.17041666666667</ixx>
            <iyy>22.01875473164394</iyy>
            <izz>1.8558380649772699</izz>
          </inertia>
        </inertial>
      </link>
      <joint name="left_joint" type="revolute">
        <parent>world</parent>
        <child>left</child>
        <axis>
          <xyz>0 0 1</xyz>
          <limit>
            <lower>-1.57</lower>
            <upper>0</upper>
          </limit>
        </axis>
        <pose>-0.338354591836735 0 0 0 0 0</pose>
      </joint>
      <plugin name="register_component" filename="libregister_component.so">
        <component name="Door">
          <v_max_door>0.5</v_max_door>
          <a_max_door>0.3</a_max_door>
          <a_nom_door>0.15</a_nom_door>
          <dx_min_door>0.01</dx_min_door>
          <f_max_door>500.0</f_max_door>
          <ros_interface>true</ros_interface>
          <door name="door4" type="DoubleSwingDoor" left_joint_name="left_joint" right_joint_name="right_joint" />
        </component>
      </plugin>
    </model>
    <model name="door5">
      <pose>22.107627551020414 -31.709056122448985 0.0 0 0 3.141592653589793</pose>
      <link name="right">
        <pose>0.7452295918367344 0 1.11 0 0 0</pose>
        <visual name="right_visual">
          <geometry>
            <box>
              <size>1.4804591836734688 0.03 2.2</size>
            </box>
          </geometry>
          <material>
            <ambient>0.5 0.25 0 0.6</ambient>
            <diffuse>0.5 0.25 0 0.6</diffuse>
            <pbr>
              <metal>
                <metalness>0.0</metalness>
              </metal>
            </pbr>
          </material>
        </visual>
        <collision name="right_collision">
          <geometry>
            <box>
              <size>1.4804591836734688 0.03 2.2</size>
            </box>
          </geometry>
          <surface>
            <contact>
              <collide_bitmask>0x02</collide_bitmask>
            </contact>
          </surface>
        </collision>
        <inertial>
          <mass>50.0</mass>
          <inertia>
            <ixx>20.17041666666667</ixx>
            <iyy>29.298997477179647</iyy>
            <izz>9.136080810512976</izz>
          </inertia>
        </inertial>
      </link>
      <joint name="right_joint" type="revolute">
        <parent>world</parent>
        <child>right</child>
        <axis>
          <xyz>0 0 -1</xyz>
          <limit>
            <lower>0</lower>
            <upper>1.57</upper>
          </limit>
        </axis>
        <pose>0.7452295918367344 0 0 0 0 0</pose>
      </joint>
      <link name="left">
        <pose>-0.7452295918367344 0 1.11 0 0 0</pose>
        <visual name="left_visual">
          <geometry>
            <box>
              <size>1.4804591836734688 0.03 2.2</size>
            </box>
          </geometry>
          <material>
            <ambient>0.5 0.25 0 0.6</ambient>
            <diffuse>0.5 0.25 0 0.6</diffuse>
            <pbr>
              <metal>
                <metalness>0.0</metalness>
              </metal>
            </pbr>
          </material>
        </visual>
        <collision name="left_collision">
          <geometry>
            <box>
              <size>1.4804591836734688 0.03 2.2</size>
            </box>
          </geometry>
          <surface>
            <contact>
              <collide_bitmask>0x02</collide_bitmask>
            </contact>
          </surface>
        </collision>
        <inertial>
          <mass>50.0</mass>
          <inertia>
            <ixx>20.17041666666667</ixx>
            <iyy>29.298997477179647</iyy>
            <izz>9.136080810512976</izz>
          </inertia>
        </inertial>
      </link>
      <joint name="left_joint" type="revolute">
        <parent>world</parent>
        <child>left</child>
        <axis>
          <xyz>0 0 -1</xyz>
          <limit>
            <lower>-1.57</lower>
            <upper>0</upper>
          </limit>
        </axis>
        <pose>-0.7452295918367344 0 0 0 0 0</pose>
      </joint>
      <plugin name="register_component" filename="libregister_component.so">
        <component name="Door">
          <v_max_door>0.5</v_max_door>
          <a_max_door>0.3</a_max_door>
          <a_nom_door>0.15</a_nom_door>
          <dx_min_door>0.01</dx_min_door>
          <f_max_door>500.0</f_max_door>
          <ros_interface>true</ros_interface>
          <door name="door5" type="DoubleSwingDoor" left_joint_name="left_joint" right_joint_name="right_joint" />
        </component>
      </plugin>
    </model>
    <include>
      <name>icc_kyoto_L1</name>
      <uri>model://icc_kyoto_L1</uri>
      <pose>0 0 0.0 0 0 0</pose>
    </include>
    <model name="door6">
      <pose>734.2375 -1243.013 12.0 0 0 3.141592653589793</pose>
      <link name="right">
        <pose>30.82775000000001 0 1.11 0 0 0</pose>
        <visual name="right_visual">
          <geometry>
            <box>
              <size>61.64550000000002 0.03 2.2</size>
            </box>
          </geometry>
          <material>
            <ambient>0.5 0.25 0 0.6</ambient>
            <diffuse>0.5 0.25 0 0.6</diffuse>
            <pbr>
              <metal>
                <metalness>0.0</metalness>
              </metal>
            </pbr>
          </material>
        </visual>
        <collision name="right_collision">
          <geometry>
            <box>
              <size>61.64550000000002 0.03 2.2</size>
            </box>
          </geometry>
          <surface>
            <contact>
              <collide_bitmask>0x02</collide_bitmask>
            </contact>
          </surface>
        </collision>
        <inertial>
          <mass>50.0</mass>
          <inertia>
            <ixx>20.17041666666667</ixx>
            <iyy>15854.19862604168</iyy>
            <izz>15834.035709375012</izz>
          </inertia>
        </inertial>
      </link>
      <joint name="right_joint" type="revolute">
        <parent>world</parent>
        <child>right</child>
        <axis>
          <xyz>0 0 -1</xyz>
          <limit>
            <lower>0</lower>
            <upper>1.57</upper>
          </limit>
        </axis>
        <pose>30.82775000000001 0 0 0 0 0</pose>
      </joint>
      <link name="left">
        <pose>-30.82775000000001 0 1.11 0 0 0</pose>
        <visual name="left_visual">
          <geometry>
            <box>
              <size>61.64550000000002 0.03 2.2</size>
            </box>
          </geometry>
          <material>
            <ambient>0.5 0.25 0 0.6</ambient>
            <diffuse>0.5 0.25 0 0.6</diffuse>
            <pbr>
              <metal>
                <metalness>0.0</metalness>
              </metal>
            </pbr>
          </material>
        </visual>
        <collision name="left_collision">
          <geometry>
            <box>
              <size>61.64550000000002 0.03 2.2</size>
            </box>
          </geometry>
          <surface>
            <contact>
              <collide_bitmask>0x02</collide_bitmask>
            </contact>
          </surface>
        </collision>
        <inertial>
          <mass>50.0</mass>
          <inertia>
            <ixx>20.17041666666667</ixx>
            <iyy>15854.19862604168</iyy>
            <izz>15834.035709375012</izz>
          </inertia>
        </inertial>
      </link>
      <joint name="left_joint" type="revolute">
        <parent>world</parent>
        <child>left</child>
        <axis>
          <xyz>0 0 -1</xyz>
          <limit>
            <lower>-1.57</lower>
            <upper>0</upper>
          </limit>
        </axis>
        <pose>-30.82775000000001 0 0 0 0 0</pose>
      </joint>
      <plugin name="register_component" filename="libregister_component.so">
        <component name="Door">
          <v_max_door>0.5</v_max_door>
          <a_max_door>0.3</a_max_door>
          <a_nom_door>0.15</a_nom_door>
          <dx_min_door>0.01</dx_min_door>
          <f_max_door>500.0</f_max_door>
          <ros_interface>true</ros_interface>
          <door name="door6" type="DoubleSwingDoor" left_joint_name="left_joint" right_joint_name="right_joint" />
        </component>
      </plugin>
    </model>
    <model name="door7">
      <pose>865.6379999999999 -1243.013 12.0 0 0 3.141592653589793</pose>
      <link name="right">
        <pose>28.750500000000017 0 1.11 0 0 0</pose>
        <visual name="right_visual">
          <geometry>
            <box>
              <size>57.491000000000035 0.03 2.2</size>
            </box>
          </geometry>
          <material>
            <ambient>0.5 0.25 0 0.6</ambient>
            <diffuse>0.5 0.25 0 0.6</diffuse>
            <pbr>
              <metal>
                <metalness>0.0</metalness>
              </metal>
            </pbr>
          </material>
        </visual>
        <collision name="right_collision">
          <geometry>
            <box>
              <size>57.491000000000035 0.03 2.2</size>
            </box>
          </geometry>
          <surface>
            <contact>
              <collide_bitmask>0x02</collide_bitmask>
            </contact>
          </surface>
        </collision>
        <inertial>
          <mass>50.0</mass>
          <inertia>
            <ixx>20.17041666666667</ixx>
            <iyy>13791.896170833352</iyy>
            <izz>13771.733254166684</izz>
          </inertia>
        </inertial>
      </link>
      <joint name="right_joint" type="revolute">
        <parent>world</parent>
        <child>right</child>
        <axis>
          <xyz>0 0 -1</xyz>
          <limit>
            <lower>0</lower>
            <upper>1.57</upper>
          </limit>
        </axis>
        <pose>28.750500000000017 0 0 0 0 0</pose>
      </joint>
      <link name="left">
        <pose>-28.750500000000017 0 1.11 0 0 0</pose>
        <visual name="left_visual">
          <geometry>
            <box>
              <size>57.491000000000035 0.03 2.2</size>
            </box>
          </geometry>
          <material>
            <ambient>0.5 0.25 0 0.6</ambient>
            <diffuse>0.5 0.25 0 0.6</diffuse>
            <pbr>
              <metal>
                <metalness>0.0</metalness>
              </metal>
            </pbr>
          </material>
        </visual>
        <collision name="left_collision">
          <geometry>
            <box>
              <size>57.491000000000035 0.03 2.2</size>
            </box>
          </geometry>
          <surface>
            <contact>
              <collide_bitmask>0x02</collide_bitmask>
            </contact>
          </surface>
        </collision>
        <inertial>
          <mass>50.0</mass>
          <inertia>
            <ixx>20.17041666666667</ixx>
            <iyy>13791.896170833352</iyy>
            <izz>13771.733254166684</izz>
          </inertia>
        </inertial>
      </link>
      <joint name="left_joint" type="revolute">
        <parent>world</parent>
        <child>left</child>
        <axis>
          <xyz>0 0 -1</xyz>
          <limit>
            <lower>-1.57</lower>
            <upper>0</upper>
          </limit>
        </axis>
        <pose>-28.750500000000017 0 0 0 0 0</pose>
      </joint>
      <plugin name="register_component" filename="libregister_component.so">
        <component name="Door">
          <v_max_door>0.5</v_max_door>
          <a_max_door>0.3</a_max_door>
          <a_nom_door>0.15</a_nom_door>
          <dx_min_door>0.01</dx_min_door>
          <f_max_door>500.0</f_max_door>
          <ros_interface>true</ros_interface>
          <door name="door7" type="DoubleSwingDoor" left_joint_name="left_joint" right_joint_name="right_joint" />
        </component>
      </plugin>
    </model>
    <model name="door8">
      <pose>924.039 -1375.3585 12.0 0 0 1.5707963267948966</pose>
      <link name="right">
        <pose>0 0 1.11 0 0 0</pose>
        <visual name="right_visual">
          <geometry>
            <box>
              <size>36.52099999999995 0.03 2.2</size>
            </box>
          </geometry>
          <material>
            <ambient>0.5 0.25 0 0.6</ambient>
            <diffuse>0.5 0.25 0 0.6</diffuse>
            <pbr>
              <metal>
                <metalness>0.0</metalness>
              </metal>
            </pbr>
          </material>
        </visual>
        <collision name="right_collision">
          <geometry>
            <box>
              <size>36.52099999999995 0.03 2.2</size>
            </box>
          </geometry>
          <surface>
            <contact>
              <collide_bitmask>0x02</collide_bitmask>
            </contact>
          </surface>
        </collision>
        <inertial>
          <mass>50.0</mass>
          <inertia>
            <ixx>20.17041666666667</ixx>
            <iyy>5577.597670833318</iyy>
            <izz>5557.434754166652</izz>
          </inertia>
        </inertial>
      </link>
      <joint name="right_joint" type="prismatic">
        <parent>world</parent>
        <child>right</child>
        <axis>
          <xyz>1 0 0</xyz>
          <limit>
            <lower>0.0</lower>
            <upper>36.53099999999995</upper>
            <effort>500.0</effort>
          </limit>
        </axis>
      </joint>
      <plugin name="register_component" filename="libregister_component.so">
        <component name="Door">
          <v_max_door>0.2</v_max_door>
          <a_max_door>0.2</a_max_door>
          <a_nom_door>0.08</a_nom_door>
          <dx_min_door>0.001</dx_min_door>
          <f_max_door>100.0</f_max_door>
          <ros_interface>true</ros_interface>
          <door name="door8" type="SlidingDoor" left_joint_name="empty_joint" right_joint_name="right_joint" />
        </component>
      </plugin>
    </model>
    <model name="door9">
      <pose>674.5 -1373.8175 12.0 0 0 1.5707963267948966</pose>
      <link name="right">
        <pose>0 0 1.11 0 0 0</pose>
        <visual name="right_visual">
          <geometry>
            <box>
              <size>36.73700000000007 0.03 2.2</size>
            </box>
          </geometry>
          <material>
            <ambient>0.5 0.25 0 0.6</ambient>
            <diffuse>0.5 0.25 0 0.6</diffuse>
            <pbr>
              <metal>
                <metalness>0.0</metalness>
              </metal>
            </pbr>
          </material>
        </visual>
        <collision name="right_collision">
          <geometry>
            <box>
              <size>36.73700000000007 0.03 2.2</size>
            </box>
          </geometry>
          <surface>
            <contact>
              <collide_bitmask>0x02</collide_bitmask>
            </contact>
          </surface>
        </collision>
        <inertial>
          <mass>50.0</mass>
          <inertia>
            <ixx>20.17041666666667</ixx>
            <iyy>5643.529870833356</iyy>
            <izz>5623.3669541666895</izz>
          </inertia>
        </inertial>
      </link>
      <joint name="right_joint" type="revolute">
        <parent>world</parent>
        <child>right</child>
        <axis>
          <xyz>0 0 1</xyz>
          <limit>
            <lower>0</lower>
            <upper>1.57</upper>
          </limit>
        </axis>
        <pose>18.373500000000035 0 0 0 0 0</pose>
      </joint>
      <plugin name="register_component" filename="libregister_component.so">
        <component name="Door">
          <v_max_door>0.5</v_max_door>
          <a_max_door>0.3</a_max_door>
          <a_nom_door>0.15</a_nom_door>
          <dx_min_door>0.01</dx_min_door>
          <f_max_door>500.0</f_max_door>
          <ros_interface>true</ros_interface>
          <door name="door9" type="SwingDoor" left_joint_name="empty_joint" right_joint_name="right_joint" />
        </component>
      </plugin>
    </model>
    <include>
      <name>icc_kyoto_L2</name>
      <uri>model://icc_kyoto_L2</uri>
      <pose>0 0 12.0 0 0 0</pose>
    </include>
    <plugin name="register_component" filename="libregister_component.so">
      <component name="Chargers">
        <rmf_charger name="tinyRobot1_charger" x="14.76336734693878" y="-7.130178571428573" z="0.0" />
        <rmf_charger name="tinyRobot2_charger" x="26.390102040816334" y="-43.52367346938777" z="0.0" />
      </component>
    </plugin>
  </world>
</sdf>
